<?xml version="1.0" ?>
<!-- =================================================================================== -->
<!-- |    This document was autogenerated by xacro from robot.xacro                    | -->
<!-- |    EDITING THIS FILE BY HAND IS NOT RECOMMENDED                                 | -->
<!-- =================================================================================== -->
<robot name="robot">
  <material name="black">
    <color rgba="0.0 0.0 0.0 1.0"/>
  </material>
  <material name="blue">
    <color rgba="0.0 0.0 0.8 1.0"/>
  </material>
  <material name="green">
    <color rgba="0.0 0.8 0.0 1.0"/>
  </material>
  <material name="grey">
    <color rgba="0.2 0.2 0.2 1.0"/>
  </material>
  <material name="silver">
    <color rgba="0.9137254901960784 0.9137254901960784 0.8470588235294118 1.0"/>
  </material>
  <material name="orange">
    <color rgba="1.0 0.4235294117647059 0.0392156862745098 1.0"/>
  </material>
  <material name="brown">
    <color rgba="0.8705882352941177 0.8117647058823529 0.7647058823529411 1.0"/>
  </material>
  <material name="red">
    <color rgba="0.54901960784 0.04705882353 0.0431372549  1.0"/>
  </material>
  <material name="gold">
    <color rgba="0.94901960784 0.75294117647 0.33725490196 0.0"/> 
  </material>
  <material name="white">
    <color rgba="1.0 1.0 1.0 1.0"/>
  </material>
  <link name="base">
    <visual>
      <origin rpy="0 0 0" xyz="0 0 0"/>
      <geometry>
        <mesh filename="../meshes_avago/trunk.STL" scale="1 1 1"/>
      </geometry>
      <material name="red"/>
    </visual>
    <collision>
      <origin rpy="0 0 0" xyz="0 0 0.05"/>
      <geometry>
        <box size="0.238 0.18 0.08"/>
      </geometry>
    </collision>
    <inertial>
      <origin rpy="0 0 0" xyz="-0.04348167 -0.00037175 0.00364394"/>
      <mass value="7.21"/>
      <inertia ixx="0.03723183" ixy="-0.00012705" ixz="-0.00663414" iyy="0.16560871" iyz="0.00003057" izz="0.17600247"/>
    </inertial>
  </link>
  <!-- Imu is fixed to the base link -->
  <joint name="unitree_imu_joint" type="fixed">
    <origin rpy="0. 0. 0." xyz="0. 0. 0."/>
    <parent link="base"/>
    <child link="unitree_imu"/>
  </joint>
  <!-- Imu link -->
  <link name="unitree_imu">
    <inertial>
      <mass value="0.01"/>
      <origin rpy="0 0 0" xyz="0 0 0"/>
      <inertia ixx="0.000001" ixy="0" ixz="0" iyy="0.000001" iyz="0" izz="0.000001"/>
    </inertial>
    <visual>
      <origin rpy="0 0 0" xyz="0 0 0"/>
      <geometry>
        <box size="0.015 0.015 0.004"/>
      </geometry>
    </visual>
    <material name="orange">
      <color rgba="255 108 10 255"/>
    </material>
  </link>
 <!-- FR HIP -->
  <joint name="FR_hip_joint" type="revolute">
    <origin rpy="0 0 0" xyz="0.250 -0.055 -0.03"/>
    <parent link="base"/>
    <child link="FR_hip"/>
    <axis xyz="1 0 0"/>
    <dynamics damping="0.0" friction="0.0"/>
    <limit effort="48.0" lower="-0.43" upper="0.43" velocity="65.0"/>
  </joint>
  <link name="FR_hip">
    <visual>
      <origin rpy="0 0 0" xyz="0 0 0"/>
      <!-- <origin rpy="${pi} 0 0" xyz="0 0 0"/> -->
      <geometry>
        <mesh filename="../meshes_avago/FR_hip_link.STL" scale="1 1 1"/>
      </geometry>
      <material name="gold"/>
    </visual>
    <!-- <collision> -->
      <!-- <origin rpy="1.5707963267948966 0 0" xyz="0 0 0"/> -->
      <!-- <geometry> -->
        <!-- <cylinder length="0.005" radius="0.035"/> -->
        <!-- <cylinder length="0.032" radius="0.035"/> -->
      <!-- </geometry> -->
    <!-- </collision> -->
    <inertial>
    <!-- mirror=-1,front_hind=1 -->
      <origin rpy="0 0 0" xyz="-0.0070899 -0.00055871 0.00376840"/>
      <mass value="0.89774"/>
      <inertia ixx="0.00068302" ixy="-0.00000081" ixz="0.00015171" iyy="0.00121328" iyz="-0.00000114" izz="0.00084452"/>
    </inertial>
  </link>
  <joint name="FR_thigh_joint" type="revolute">
    <!-- c -->
    <!-- <origin rpy="0 0 0" xyz="0 ${thigh_offset*mirror} 0"/> -->
    <origin rpy="0 0.0 0" xyz="0 -0.090499 0"/>
    <parent link="FR_hip"/>
    <child link="FR_thigh"/>
    <!-- <axis xyz="0 -1 0"/> -->
    <axis xyz="0 1 0"/>
    <dynamics damping="0.0" friction="0.0"/>
    <limit effort="48.0" lower="-1" upper="1.79" velocity="65.0"/>

  </joint>
  <link name="FR_thigh">
    <visual>
      <origin rpy="0 0 0" xyz="0 0 0"/>
      <geometry>
        <mesh filename="../meshes_avago/FR_thigh_link.STL" scale="1 1 1"/>
      </geometry>
      <material name="gold"/>
    </visual>
    <collision>
      <origin rpy="0 1.5707963267948966 0" xyz="0 0 -0.1"/>
      <!-- <origin rpy="0 ${pi/2.0+0.1} 0" xyz="0 0 ${-thigh_length/2.0}"/> -->
      <geometry>
        <box size="0.2 0.03 0.03"/>
      </geometry>
    </collision>
    <!-- <collision> -->
      <!-- <origin rpy="1.5707963267948966 0 0" xyz="0 0 0"/> -->
      <!-- <geometry> -->
        <!-- <cylinder length="0.015" radius="0.035"/> -->
        <!-- <cylinder length="0.035" radius="0.035"/> -->
      <!-- </geometry> -->
    <!-- </collision> -->
    <inertial>
      <origin rpy="0 0 0" xyz="-0.00390636 0.01800135 -0.02378433"/>
      <mass value="1.36914585"/>
      <inertia ixx="0.00610736" ixy="-0.00015575" ixz="-0.00032422" iyy="0.00602303" iyz="-0.00070505" izz="0.00191976"/>
    </inertial>
  </link>
  <joint name="FR_calf_joint" type="revolute">
    <!-- cc -->
    <origin rpy="0 0 0" xyz="0 0 -0.20"/>
    <parent link="FR_thigh"/>
    <child link="FR_calf"/>
    <axis xyz="0 1 0"/>
    <dynamics damping="0.0" friction="0.0"/>
    <limit effort="48.0" lower="-2.6" upper="-0.5" velocity="65.0"/>
  </joint>
  <link name="FR_calf">
    <visual>
      <origin rpy="0 0 0" xyz="0 0 0"/>
      <geometry>
        <mesh filename="../meshes_avago/FL_calf_link.STL" scale="1 1 1"/>
      </geometry>
      <material name="red"/>
    </visual>
    <collision>
      <origin rpy="0 1.5707963267948966 0" xyz="0 0 -0.12315"/>
      <geometry>
        <box size="0.2463 0.018 0.015"/>
      </geometry>
    </collision>
    <inertial>
      <origin rpy="0 0 0" xyz="0.00240943 -0.00008761 -0.14524141"/>
      <mass value="0.33297772"/>
      <inertia ixx="0.00268671" ixy="-0.00000014" ixz="0.00017624" iyy="0.00273548" iyz="-0.00000255" izz="0.00011247"/>
    </inertial>
  </link>
  <joint name="FR_foot_fixed" type="fixed" dont_collapse="true">
    <origin rpy="0 0 0" xyz="0 0 -0.2463"/>
    <parent link="FR_calf"/>
    <child link="FR_foot"/>
  </joint>
  <link name="FR_foot">
    <visual>
      <origin rpy="0 0 0" xyz="0 0 0"/>
      <geometry>
        <sphere radius="0.0247"/>
        <!-- <mesh filename="../meshes_avago/$(arg robot_type)/FL_toe_link.STL" scale="1 1 1"/> -->
      </geometry>
      <material name="gold"/>
    </visual>
    <collision>
      <origin rpy="0 0 0" xyz="0 0 0"/>
      <geometry>
        <sphere radius="0.0247"/>
      </geometry>
    </collision>
    <inertial>
      <mass value="0.0087187"/>
      <origin rpy="0 0 0" xyz="-0.0042403 0 -0.0056271"/>
      <inertia ixx="1.20e-06" ixy="0" ixz="0" iyy="1.56e-06" iyz="0" izz="1.40e-06"/>
    </inertial>
  </link>
  <!-- FL hip -->
  <joint name="FL_hip_joint" type="revolute">
    <origin rpy="0 0 0" xyz="0.250 0.055 -0.03"/>
    <parent link="base"/>
    <child link="FL_hip"/>
    <axis xyz="1 0 0"/>
    <dynamics damping="0.0" friction="0.0"/>
    <limit effort="48.0" lower="-0.43" upper="0.43" velocity="65.0"/>
  </joint>
  <link name="FL_hip">
    <visual>
      <origin rpy="0 0 0" xyz="0 0 0"/>
      <geometry>
        <mesh filename="../meshes_avago/FL_hip_link.STL" scale="1 1 1"/>
      </geometry>
      <material name="gold"/>
    </visual>
    <!-- <collision> -->
      <!-- <origin rpy="1.5707963267948966 0 0" xyz="0 0 0"/> -->
      <!-- <geometry> -->
        <!-- <cylinder length="0.005" radius="0.035"/> -->
        <!-- <cylinder length="0.032" radius="0.035"/> -->
      <!-- </geometry> -->
    <!-- </collision> -->
    <inertial>
    <!-- mirror=1,front_hind=1 -->
      <origin rpy="0 0 0" xyz="-0.0070899 0.00055871 0.00376840"/>
      <mass value="0.89774"/>
      <inertia ixx="0.00068302" ixy="0.00000081" ixz="0.00015171" iyy="0.00121328" iyz="0.00000114" izz="0.00084452"/>
    </inertial>
  </link>
  <joint name="FL_thigh_joint" type="revolute">
    <!-- c -->
    <!-- <origin rpy="0 0 0" xyz="0 ${thigh_offset*mirror} 0"/> -->
    <origin rpy="0 0.0 0" xyz="0 0.090499 0"/>
    <parent link="FL_hip"/>
    <child link="FL_thigh"/>
    <!-- <axis xyz="0 -1 0"/> -->
    <axis xyz="0 1 0"/>
    <dynamics damping="0.0" friction="0.0"/>
    <limit effort="48.0" lower="-1" upper="1.79" velocity="65.0"/>
  </joint>
  <link name="FL_thigh">
    <visual>
      <origin rpy="0 0 0" xyz="0 0 0"/>
      <geometry>
        <mesh filename="../meshes_avago/FL_thigh_link.STL" scale="1 1 1"/>
      </geometry>
      <material name="gold"/>
    </visual>
    <collision>
      <origin rpy="0 1.5707963267948966 0" xyz="0 0 -0.1"/>
      <!-- <origin rpy="0 ${pi/2.0+0.1} 0" xyz="0 0 ${-thigh_length/2.0}"/> -->
      <geometry>
        <box size="0.2 0.03 0.03"/>
      </geometry>
    </collision>
    <!-- <collision> -->
      <!-- <origin rpy="1.5707963267948966 0 0" xyz="0 0 0"/> -->
      <!-- <geometry> -->
        <!-- <cylinder length="0.035" radius="0.035"/> -->
        <!-- <cylinder length="0.015" radius="0.035"/> -->
      <!-- </geometry> -->
    <!-- </collision> -->
    <inertial>
      <origin rpy="0 0 0" xyz="-0.00390636 -0.01800135 -0.02378433"/>
      <mass value="1.36914585"/>
      <inertia ixx="0.00610736" ixy="0.00015575" ixz="-0.00032422" iyy="0.00602303" iyz="0.00070505" izz="0.00191976"/>
    </inertial>
  </link>
  <joint name="FL_calf_joint" type="revolute">
    <!-- cc -->
    <origin rpy="0 0 0" xyz="0 0 -0.2"/>
    <parent link="FL_thigh"/>
    <child link="FL_calf"/>
    <axis xyz="0 1 0"/>
    <dynamics damping="0.0" friction="0.0"/>
    <limit effort="48.0" lower="-2.6" upper="-0.5" velocity="65.0"/>
  </joint>
  <link name="FL_calf">
    <visual>
      <origin rpy="0 0 0" xyz="0 0 0"/>
      <geometry>
        <mesh filename="../meshes_avago/FL_calf_link.STL" scale="1 1 1"/>
      </geometry>
      <material name="red"/>
    </visual>
    <collision>
      <origin rpy="0 1.5707963267948966 0" xyz="0 0 -0.12315"/>
      <geometry>
        <box size="0.2463 0.018 0.015"/>
      </geometry>
    </collision>
    <inertial>
      <origin rpy="0 0 0" xyz="0.00240943 -0.00008761 -0.14524141"/>
      <mass value="0.33297772"/>
      <inertia ixx="0.00268671" ixy="-0.00000014" ixz="0.00017624" iyy="0.00273548" iyz="-0.00000255" izz="0.00011247"/>
    </inertial>
  </link>
  <joint name="FL_foot_fixed" type="fixed" dont_collapse="true">
    <origin rpy="0 0 0" xyz="0 0 -0.2463"/>
    <parent link="FL_calf"/>
    <child link="FL_foot"/>
  </joint>
  <link name="FL_foot">
    <visual>
      <origin rpy="0 0 0" xyz="0 0 0"/>
      <geometry>
        <sphere radius="0.0247"/>
        <!-- <mesh filename="../meshes_avago/$(arg robot_type)/FL_toe_link.STL" scale="1 1 1"/> -->
      </geometry>
      <material name="gold"/>
    </visual>
    <collision>
      <origin rpy="0 0 0" xyz="0 0 0"/>
      <geometry>
        <sphere radius="0.0247"/>
      </geometry>
    </collision>
    <inertial>
      <mass value="0.0087187"/>
      <origin rpy="0 0 0" xyz="-0.0042403 0 -0.0056271"/>
      <inertia ixx="1.20e-06" ixy="0" ixz="0" iyy="1.56e-06" iyz="0" izz="1.40e-06"/>
    </inertial>
  </link>

<!-- RR -->
  <joint name="RR_hip_joint" type="revolute">
    <origin rpy="0 0 0" xyz="-0.250 -0.055 -0.03"/>
    <parent link="base"/>
    <child link="RR_hip"/>
    <axis xyz="1 0 0"/>
    <dynamics damping="0.0" friction="0.0"/>
    <limit effort="48.0" lower="-0.43" upper="0.43" velocity="65.0"/>
  </joint>
  <link name="RR_hip">
    <visual>
      <origin rpy="0 0 3.141592653589793" xyz="0 0 0"/>
      <!-- <origin rpy="${pi} ${pi} 0" xyz="0 0 0"/> -->
      <geometry>
        <mesh filename="../meshes_avago/FL_hip_link.STL" scale="1 1 1"/>
      </geometry>
      <material name="gold"/>
    </visual>
    <!-- <collision> -->
      <!-- <origin rpy="1.5707963267948966 0 0" xyz="0 0 0"/> -->
      <!-- <geometry> -->
        <!-- <cylinder length="0.005" radius="0.035"/> -->
        <!-- <cylinder length="0.032" radius="0.035"/> -->
      <!-- </geometry> -->
    <!-- </collision> -->
    <inertial>
    <!-- mirror=-1,front_hind=-1 -->
      <origin rpy="0 0 0" xyz="0.0070899 -0.00055871 0.00376840"/>
      <mass value="0.89774"/>
      <inertia ixx="0.00068302" ixy="0.00000081" ixz="-0.00015171" iyy="0.00121328" iyz="-0.00000114" izz="0.00084452"/>
    </inertial>
  </link>
  <joint name="RR_thigh_joint" type="revolute">
    <!-- c -->
    <!-- <origin rpy="0 0 0" xyz="0 ${thigh_offset*mirror} 0"/> -->
    <origin rpy="0 0.0 0" xyz="0 -0.090499 0"/>
    <parent link="RR_hip"/>
    <child link="RR_thigh"/>
    <!-- <axis xyz="0 -1 0"/> -->
    <axis xyz="0 1 0"/>
    <dynamics damping="0.0" friction="0.0"/>
    <limit effort="48.0" lower="-1" upper="1.79" velocity="65.0"/>
  </joint>
  <link name="RR_thigh">
    <visual>
      <origin rpy="0 0 0" xyz="0 0 0"/>
      <geometry>
        <mesh filename="../meshes_avago/FR_thigh_link.STL" scale="1 1 1"/>
      </geometry>
      <material name="gold"/>
    </visual>
    <collision>
      <origin rpy="0 1.5707963267948966 0" xyz="0 0 -0.1"/>
      <!-- <origin rpy="0 ${pi/2.0+0.1} 0" xyz="0 0 ${-thigh_length/2.0}"/> -->
      <geometry>
        <box size="0.2 0.03 0.03"/>
      </geometry>
    </collision>
    <!-- <collision> -->
      <!-- <origin rpy="1.5707963267948966 0 0" xyz="0 0 0"/> -->
      <!-- <geometry> -->
        <!-- <cylinder length="0.015" radius="0.035"/> -->
        <!-- <cylinder length="0.035" radius="0.035"/> -->
      <!-- </geometry> -->
    <!-- </collision> -->
    <inertial>
      <origin rpy="0 0 0" xyz="-0.00390636 0.01800135 -0.02378433"/>
      <mass value="1.36914585"/>
      <inertia ixx="0.00610736" ixy="-0.00015575" ixz="-0.00032422" iyy="0.00602303" iyz="-0.00070505" izz="0.00191976"/>
    </inertial>
  </link>
  <joint name="RR_calf_joint" type="revolute">
    <!-- cc -->
    <origin rpy="0 0 0" xyz="0 0 -0.20"/>
    <parent link="RR_thigh"/>
    <child link="RR_calf"/>
    <axis xyz="0 1 0"/>
    <dynamics damping="0.0" friction="0.0"/>
    <limit effort="48.0" lower="-2.6" upper="-0.5" velocity="65.0"/>
  </joint>
  <link name="RR_calf">
    <visual>
      <origin rpy="0 0 0" xyz="0 0 0"/>
      <geometry>
        <mesh filename="../meshes_avago/FL_calf_link.STL" scale="1 1 1"/>
      </geometry>
      <material name="red"/>
    </visual>
    <collision>
      <origin rpy="0 1.5707963267948966 0" xyz="0 0 -0.12315"/>
      <geometry>
        <box size="0.2463 0.018 0.015"/>
      </geometry>
    </collision>
    <inertial>
      <origin rpy="0 0 0" xyz="0.00240943 -0.00008761 -0.14524141"/>
      <mass value="0.33297772"/>
      <inertia ixx="0.00268671" ixy="-0.00000014" ixz="0.00017624" iyy="0.00273548" iyz="-0.00000255" izz="0.00011247"/>
    </inertial>
  </link>
  <joint name="RR_foot_fixed" type="fixed" dont_collapse="true">
    <origin rpy="0 0 0" xyz="0 0 -0.2463"/>
    <parent link="RR_calf"/>
    <child link="RR_foot"/>
  </joint>
  <link name="RR_foot">
    <visual>
      <origin rpy="0 0 0" xyz="0 0 0"/>
      <geometry>
        <sphere radius="0.0247"/>
        <!-- <mesh filename="../meshes_avago/$(arg robot_type)/FL_toe_link.STL" scale="1 1 1"/> -->
      </geometry>
      <material name="gold"/>
    </visual>
    <collision>
      <origin rpy="0 0 0" xyz="0 0 0"/>
      <geometry>
        <sphere radius="0.0247"/>
      </geometry>
    </collision>
    <!-- <inertial>
                <mass value="${foot_mass}"/>
                <inertia
                        ixx="${(2*foot_mass)/5.0*(foot_radius*foot_radius)}" ixy="0.0" ixz="0.0"
                        iyy="${(2*foot_mass)/5.0*(foot_radius*foot_radius)}" iyz="0.0"
                        izz="${(2*foot_mass)/5.0*(foot_radius*foot_radius)}"/>
            </inertial> -->
    <!-- <inertial>
                <mass value="${0.0}"/>
                <inertia
                        ixx="0.0" ixy="0.0" ixz="0.0"
                        iyy="0.0" iyz="0.0"
                        izz="0.0"/>
            </inertial> -->
    <inertial>
      <mass value="0.0087187"/>
      <origin rpy="0 0 0" xyz="-0.0042403 0 -0.0056271"/>
      <inertia ixx="1.20e-06" ixy="0" ixz="0" iyy="1.56e-06" iyz="0" izz="1.40e-06"/>
    </inertial>
  </link>

<!-- RL hip-->
  <joint name="RL_hip_joint" type="revolute">
    <origin rpy="0 0 0" xyz="-0.250 0.055 -0.03"/>
    <parent link="base"/>
    <child link="RL_hip"/>
    <axis xyz="1 0 0"/>
    <dynamics damping="0.0" friction="0.0"/>
    <limit effort="48.0" lower="-0.43" upper="0.43" velocity="65.0"/>
  </joint>
  <link name="RL_hip">
    <visual>
      <origin rpy="0 0 3.141592653589793" xyz="0 0 0"/>
      <!-- <origin rpy="0 ${pi} 0" xyz="0 0 0"/> -->
      <geometry>
        <mesh filename="../meshes_avago/FR_hip_link.STL" scale="1 1 1"/>
      </geometry>
      <material name="gold"/>
    </visual>
    <!-- <collision> -->
      <!-- <origin rpy="1.5707963267948966 0 0" xyz="0 0 0"/> -->
      <!-- <geometry> -->
        <!-- <cylinder length="0.005" radius="0.035"/> -->
        <!-- <cylinder length="0.032" radius="0.035"/> -->
      <!-- </geometry> -->
    <!-- </collision> -->
    <inertial>
    <!-- mirror=1,front_hind=-1 -->
      <origin rpy="0 0 0" xyz="0.0070899 0.00055871 0.00376840"/>
      <mass value="0.89774"/>
      <inertia ixx="0.00068302" ixy="-0.00000081" ixz="-0.00015171" iyy="0.00121328" iyz="0.00000114" izz="0.00084452"/>
    </inertial>
  </link>
  <joint name="RL_thigh_joint" type="revolute">
    <!-- c -->
    <!-- <origin rpy="0 0 0" xyz="0 ${thigh_offset*mirror} 0"/> -->
    <origin rpy="0 0.0 0" xyz="0 0.090499 0"/>
    <parent link="RL_hip"/>
    <child link="RL_thigh"/>
    <!-- <axis xyz="0 -1 0"/> -->
    <axis xyz="0 1 0"/>
    <dynamics damping="0.0" friction="0.0"/>
    <limit effort="48.0" lower="-1" upper="1.79" velocity="65.0"/>
  </joint>
  <link name="RL_thigh">
    <visual>
      <origin rpy="0 0 0" xyz="0 0 0"/>
      <geometry>
        <mesh filename="../meshes_avago/FL_thigh_link.STL" scale="1 1 1"/>
      </geometry>
      <material name="gold"/>
    </visual>
    <collision>
      <origin rpy="0 1.5707963267948966 0" xyz="0 0 -0.1"/>
      <!-- <origin rpy="0 ${pi/2.0+0.1} 0" xyz="0 0 ${-thigh_length/2.0}"/> -->
      <geometry>
        <box size="0.2 0.03 0.03"/>
      </geometry>
    </collision>
    <!-- <collision> -->
      <!-- <origin rpy="1.5707963267948966 0 0" xyz="0 0 0"/> -->
      <!-- <geometry> -->
        <!-- <cylinder length="0.015" radius="0.035"/> -->
        <!-- <cylinder length="0.035" radius="0.035"/> -->
      <!-- </geometry> -->
    <!-- </collision> -->
    <inertial>
      <origin rpy="0 0 0" xyz="-0.00390636 -0.01800135 -0.02378433"/>
      <mass value="1.36914585"/>
      <inertia ixx="0.00610736" ixy="0.00015575" ixz="-0.00032422" iyy="0.00602303" iyz="0.00070505" izz="0.00191976"/>
    </inertial>
  </link>
  <joint name="RL_calf_joint" type="revolute">
    <!-- cc -->
    <origin rpy="0 0 0" xyz="0 0 -0.20"/>
    <parent link="RL_thigh"/>
    <child link="RL_calf"/>
    <axis xyz="0 1 0"/>
    <dynamics damping="0.0" friction="0.0"/>
    <limit effort="48.0" lower="-2.6" upper="-0.5" velocity="65.0"/>
  </joint>
  <link name="RL_calf">
    <visual>
      <origin rpy="0 0 0" xyz="0 0 0"/>
      <geometry>
        <mesh filename="../meshes_avago/FL_calf_link.STL" scale="1 1 1"/>
      </geometry>
      <material name="red"/>
    </visual>
    <collision>
      <origin rpy="0 1.5707963267948966 0" xyz="0 0 -0.12315"/>
      <geometry>
        <box size="0.2463 0.018 0.015"/>
      </geometry>
    </collision>
    <inertial>
      <origin rpy="0 0 0" xyz="0.00240943 -0.00008761 -0.14524141"/>
      <mass value="0.33297772"/>
      <inertia ixx="0.00268671" ixy="-0.00000014" ixz="0.00017624" iyy="0.00273548" iyz="-0.00000255" izz="0.00011247"/>
    </inertial>
  </link>
  <joint name="RL_foot_fixed" type="fixed" dont_collapse="true">
    <origin rpy="0 0 0" xyz="0 0 -0.2463"/>
    <parent link="RL_calf"/>
    <child link="RL_foot"/>
  </joint>
  <link name="RL_foot">
    <visual>
      <origin rpy="0 0 0" xyz="0 0 0"/>
      <geometry>
        <sphere radius="0.0247"/>
        <!-- <mesh filename="../meshes_avago/$(arg robot_type)/FL_toe_link.STL" scale="1 1 1"/> -->
      </geometry>
      <material name="gold"/>
    </visual>
    <collision>
      <origin rpy="0 0 0" xyz="0 0 0"/>
      <geometry>
        <sphere radius="0.0247"/>
      </geometry>
    </collision>
    <!-- <inertial>
                <mass value="${foot_mass}"/>
                <inertia
                        ixx="${(2*foot_mass)/5.0*(foot_radius*foot_radius)}" ixy="0.0" ixz="0.0"
                        iyy="${(2*foot_mass)/5.0*(foot_radius*foot_radius)}" iyz="0.0"
                        izz="${(2*foot_mass)/5.0*(foot_radius*foot_radius)}"/>
            </inertial> -->
    <!-- <inertial>
                <mass value="${0.0}"/>
                <inertia
                        ixx="0.0" ixy="0.0" ixz="0.0"
                        iyy="0.0" iyz="0.0"
                        izz="0.0"/>
            </inertial> -->
    <inertial>
      <mass value="0.0087187"/>
      <origin rpy="0 0 0" xyz="-0.0042403 0 -0.0056271"/>
      <inertia ixx="1.20e-06" ixy="0" ixz="0" iyy="1.56e-06" iyz="0" izz="1.40e-06"/>
    </inertial>
  </link>

  <!-- Robot Footprint
  <joint name="footprint_joint" type="fixed">
    <parent link="base"/>
    <child link="base_footprint"/>
    <origin rpy="0 0 0" xyz="0.0 0.0 -0.2"/>
  </joint>
  <link name="base_footprint">
    <inertial>
      <origin rpy="1.5707963267948966 0 1.5707963267948966" xyz="0 0 0"/>
      <mass value="0.001"/>
      <inertia ixx="0.0" ixy="0.0" ixz="0.0" iyy="0.0" iyz="0.0" izz="0.0"/>
    </inertial>
  </link> -->
  <!-- <xacro:lidar parent="base" xyz="-0.065 0. 0.1" rpy="0. 0. 0."/> -->
</robot>

