<?xml version="1.0" ?>
<!-- =================================================================================== -->
<!-- |    This document was autogenerated by xacro from /home/yong/ros_ws/src/legged_control/legged_examples/legged_ngergo/legged_ngergo_description/urdf/robot.xacro | -->
<!-- |    EDITING THIS FILE BY HAND IS NOT RECOMMENDED                                 | -->
<!-- =================================================================================== -->
<robot name="robot">
  <material name="black">
    <color rgba="0.0 0.0 0.0 1.0"/>
  </material>
  <material name="blue">
    <color rgba="0.0 0.0 0.8 1.0"/>
  </material>
  <material name="green">
    <color rgba="0.0 0.8 0.0 1.0"/>
  </material>
  <material name="grey">
    <color rgba="0.2 0.2 0.2 1.0"/>
  </material>
  <material name="silver">
    <color rgba="0.9137254901960784 0.9137254901960784 0.8470588235294118 1.0"/>
  </material>
  <material name="orange">
    <color rgba="1.0 0.4235294117647059 0.0392156862745098 1.0"/>
  </material>
  <material name="brown">
    <color rgba="0.8705882352941177 0.8117647058823529 0.7647058823529411 1.0"/>
  </material>
  <material name="gold">
    <color rgba="0.94901960784 0.75294117647 0.33725490196 0.0"/> 
  </material>
  <material name="red">
  <!-- aa0505 -->
    <!--color rgba="0.66666666667 0.01960784314 0.01960784314 1.0"/-->
    <color rgba="0.54901960784 0.04705882353 0.0431372549  1.0"/>
  </material>
  <material name="white">
    <color rgba="1.0 1.0 1.0 1.0"/>
  </material>
  
  <link name="base">
    <visual>
      <origin rpy="0 0 0" xyz="0 0 0"/>
      <geometry>
        <mesh filename="../mesh_ngergo/trunk.STL" scale="1 1 1"/>
      </geometry>
      <material name="red"/>
    </visual>
    <collision>
      <origin rpy="0 0 0" xyz="0 0 0"/>
      <geometry>
        <!--box size="0.238 0.18 0.1"/-->
        <mesh filename="../mesh_ngergo/trunk.STL" scale="1 1 1"/>
      </geometry>
    </collision>
    <inertial>
      <origin rpy="0 0 0" xyz="0.03164293 0.00124456 0.03218306"/>
      <mass value="5.4752965"/>
      <inertia ixx="0.03315961" ixy="0.00041393" ixz="-0.01397597" iyy="0.08487646" iyz="0.00013335" izz="0.07401286"/>
    </inertial>
  </link>
  <!-- Imu is fixed to the base link -->
  <joint name="unitree_imu_joint" type="fixed">
    <origin rpy="0. 0. 0." xyz="0. 0. 0."/>
    <parent link="base"/>
    <child link="unitree_imu"/>
  </joint>
  <!-- Imu link -->
  <link name="unitree_imu">
    <inertial>
      <mass value="0.01"/>
      <origin rpy="0 0 0" xyz="0 0 0"/>
      <inertia ixx="0.000001" ixy="0" ixz="0" iyy="0.000001" iyz="0" izz="0.000001"/>
    </inertial>
    <visual>
      <origin rpy="0 0 0" xyz="0 0 0"/>
      <geometry>
        <box size="0.015 0.015 0.004"/>
      </geometry>
    </visual>
    <material name="orange">
      <color rgba="255 108 10 255"/>
    </material>
  </link>
  
  <joint name="FR_hip_joint" type="revolute">
    <origin rpy="0 0 0" xyz="0.17185 -0.0436 -0.0"/>
    <parent link="base"/>
    <child link="FR_hip"/>
    <axis xyz="1 0 0"/>
    <dynamics damping="0.0" friction="0.0"/>
    <limit effort="20" lower="-0.34" upper="0.34" velocity="13.25"/>
  </joint>
  <link name="FR_hip">
    <visual>
      <origin rpy="0 0 0" xyz="0 0 0"/>
      <!-- <origin rpy="${pi} 0 0" xyz="0 0 0"/> -->
      <geometry>
        <mesh filename="../mesh_ngergo/FR_hip_link.STL" scale="1 1 1"/>
      </geometry>
      <material name="white"/>
    </visual>
   
    <inertial>
      <origin rpy="0 0 0" xyz="-0.00181499 -0.00647781 -6.314e-05"/>
      <mass value="0.45381624"/>
      <inertia ixx="0.00033634" ixy="9.86e-06" ixz="-6.5e-07" iyy="0.0002604" iyz="-1.26e-06" izz="0.00036201"/>
    </inertial>
  </link>
  <joint name="FR_thigh_joint" type="revolute">
    <!-- c -->
    <!-- <origin rpy="0 0 0" xyz="0 ${thigh_offset*mirror} 0"/> -->
    <origin rpy="0 0.0 0" xyz="0 -0.1043 0"/>
    <parent link="FR_hip"/>
    <child link="FR_thigh"/>
    <!-- <axis xyz="0 -1 0"/> -->
    <axis xyz="0 1 0"/>
    <dynamics damping="0.0" friction="0.0"/>
    <limit effort="20" lower="-1" upper="2.64" velocity="13.25"/>
  </joint>
  <link name="FR_thigh">
    <visual>
      <origin rpy="0 0 0" xyz="0 0 0"/>
      <geometry>
        <mesh filename="../mesh_ngergo/FR_thigh_link.STL"  scale="1 1 1"/>
      </geometry>
      <material name="white"/>
    </visual>
    <collision>
      <origin rpy="0 1.5707963267948966 0" xyz="0 0 -0.07511"/>
      <geometry>
        <box size="0.15022 0.03 0.03"/>
      </geometry>
    </collision>
    <!-- <collision>
      <origin rpy="1.5707963267948966 0 0" xyz="0 0 0"/>
      <geometry>
        <cylinder length="0.035" radius="0.035"/>
      </geometry>
    </collision> -->
    <inertial>
      <origin rpy="0 0 0" xyz="-0.00256023 0.02066587 -0.01932269"/>
      <mass value="0.71506207"/>
      <inertia ixx="0.00189952" ixy="-4.028e-05" ixz="-0.00011453" iyy="0.00162545" iyz="-0.0002761" izz="0.00071971"/>
    </inertial>
  </link>
  <joint name="FR_calf_joint" type="revolute">
    <!-- cc -->
    <origin rpy="0 0 0" xyz="0 0 -0.15022"/>
    <parent link="FR_thigh"/>
    <child link="FR_calf"/>
    <axis xyz="0 1 0"/>
    <dynamics damping="0.0" friction="0.0"/>
    <limit effort="20" lower="-2.64" upper="-0.5" velocity="13.25"/>
  </joint>
  <link name="FR_calf">
    <visual>
      <origin rpy="0 0 0" xyz="0 0 0"/>
      <geometry>
        <mesh filename="../mesh_ngergo/FR_calf_link.STL" scale="1 1 1"/>
      </geometry>
      <material name="red"/>
    </visual>
    <collision>
      <origin rpy="0 1.5707963267948966 0" xyz="0 0 -0.074965"/>
      <geometry>
        <box size="0.14993 0.018 0.015"/>
      </geometry>
    </collision>
    <inertial>
      <origin rpy="0 0 0" xyz="0.00311164 -0.00026025 -0.0875749"/>
      <mass value="0.1160051"/>
      <inertia ixx="0.00036493" ixy="-6e-08" ixz="7.1e-07" iyy="0.00036973" iyz="2.97e-06" izz="2.582e-05"/>
    </inertial>
  </link>
  <joint name="FR_foot_fixed" type="fixed" dont_collapse="true">
    <origin rpy="0 0 0" xyz="0 0 -0.14993"/>
    <parent link="FR_calf"/>
    <child link="FR_foot"/>
  </joint>
  <link name="FR_foot">
    <visual>
      <origin rpy="0 0 0" xyz="0 0 0"/>
      <geometry>
        <sphere radius="0.02249"/>
        <!-- <mesh filename="package://legged_newgo_description/meshes/$(arg robot_type)/FL_toe_link.STL" scale="1 1 1"/> -->
      </geometry>
      <material name="white"/>
    </visual>
    <collision>
      <origin rpy="0 0 0" xyz="0 0 0"/>
      <geometry>
        <sphere radius="0.02249"/>
      </geometry>
    </collision>
    <inertial>
      <mass value="0.05"/>
      <inertia ixx="1.0116002e-05" ixy="0.0" ixz="0.0" iyy="1.0116002e-05" iyz="0.0" izz="1.0116002e-05"/>
    </inertial>
  </link>
  
  <joint name="FL_hip_joint" type="revolute">
    <origin rpy="0 0 0" xyz="0.17185 0.0436 -0.0"/>
    <parent link="base"/>
    <child link="FL_hip"/>
    <axis xyz="1 0 0"/>
    <dynamics damping="0.0" friction="0.0"/>
    <limit effort="20" lower="-0.34" upper="0.34" velocity="13.25"/>
  </joint>
  <link name="FL_hip">
    <visual>
      <origin rpy="0 0 0" xyz="0 0 0"/>
      <geometry>
        <mesh filename="../mesh_ngergo/FL_hip_link.STL" scale="1 1 1"/>
      </geometry>
      <material name="white"/>
    </visual>
    
    <inertial>
      <origin rpy="0 0 0" xyz="-0.00181499 0.00647781 -6.314e-05"/>
      <mass value="0.45381624"/>
      <inertia ixx="0.00033634" ixy="-9.86e-06" ixz="-6.5e-07" iyy="0.0002604" iyz="1.26e-06" izz="0.00036201"/>
    </inertial>
  </link>
  <joint name="FL_thigh_joint" type="revolute">
    <!-- c -->
    <!-- <origin rpy="0 0 0" xyz="0 ${thigh_offset*mirror} 0"/> -->
    <origin rpy="0 0.0 0" xyz="0 0.1034 0"/>
    <parent link="FL_hip"/>
    <child link="FL_thigh"/>
    <!-- <axis xyz="0 -1 0"/> -->
    <axis xyz="0 1 0"/>
    <dynamics damping="0.0" friction="0.0"/>
    <limit effort="20" lower="-1" upper="2.64" velocity="13.25"/>
  </joint>
  <link name="FL_thigh">
    <visual>
      <origin rpy="0 0 0" xyz="0 0 0"/>
      <geometry>
        <mesh filename="../mesh_ngergo/FL_thigh_link.STL" scale="1 1 1"/>
      </geometry>
      <material name="white"/>
    </visual>
    <collision>
      <origin rpy="0 1.5707963267948966 0" xyz="0 0 -0.07511"/>
      <geometry>
        <box size="0.15022 0.03 0.03"/>
      </geometry>
    </collision>
    
    <inertial>
      <origin rpy="0 0 0" xyz="-0.00256023 -0.02066587 -0.01932269"/>
      <mass value="0.71506207"/>
      <inertia ixx="0.00189952" ixy="4.028e-05" ixz="-0.00011453" iyy="0.00162545" iyz="0.0002761" izz="0.00071971"/>
    </inertial>
  </link>
  <joint name="FL_calf_joint" type="revolute">
    <!-- cc -->
    <origin rpy="0 0 0" xyz="0 0 -0.15022"/>
    <parent link="FL_thigh"/>
    <child link="FL_calf"/>
    <axis xyz="0 1 0"/>
    <dynamics damping="0.0" friction="0.0"/>
    <limit effort="20" lower="-2.64" upper="-0.5" velocity="13.25"/>
  </joint>
  <link name="FL_calf">
    <visual>
      <origin rpy="0 0 0" xyz="0 0 0"/>
      <geometry>
        <mesh filename="../mesh_ngergo/FL_calf_link.STL" scale="1 1 1"/>
      </geometry>
      <material name="red"/>
    </visual>
    <collision>
      <origin rpy="0 1.5707963267948966 0" xyz="0 0 -0.074965"/>
      <geometry>
        <box size="0.14993 0.018 0.015"/>
      </geometry>
    </collision>
    <inertial>
      <origin rpy="0 0 0" xyz="0.00311164 -0.00026025 -0.0875749"/>
      <mass value="0.1160051"/>
      <inertia ixx="0.00036493" ixy="-6e-08" ixz="7.1e-07" iyy="0.00036973" iyz="2.97e-06" izz="2.582e-05"/>
    </inertial>
  </link>
  <joint name="FL_foot_fixed" type="fixed" dont_collapse="true">
    <origin rpy="0 0 0" xyz="0 0 -0.14993"/>
    <parent link="FL_calf"/>
    <child link="FL_foot"/>
  </joint>
  <link name="FL_foot">
    <visual>
      <origin rpy="0 0 0" xyz="0 0 0"/>
      <geometry>
        <sphere radius="0.02249"/>
        <!-- <mesh filename="package://legged_ngergo_description/meshes/$(arg robot_type)/FL_toe_link.STL" scale="1 1 1"/> -->
      </geometry>
      <material name="white"/>
    </visual>
    <collision>
      <origin rpy="0 0 0" xyz="0 0 0"/>
      <geometry>
        <sphere radius="0.02249"/>
      </geometry>
    </collision>
    
    <inertial>
      <mass value="0.05"/>
      <inertia ixx="1.0116002e-05" ixy="0.0" ixz="0.0" iyy="1.0116002e-05" iyz="0.0" izz="1.0116002e-05"/>
    </inertial>
  </link>
  
  
  <joint name="RR_hip_joint" type="revolute">
    <origin rpy="0 0 0" xyz="-0.17185 -0.0436 -0.0"/>
    <parent link="base"/>
    <child link="RR_hip"/>
    <axis xyz="1 0 0"/>
    <dynamics damping="0.0" friction="0.0"/>
    <limit effort="20" lower="-0.34" upper="0.34" velocity="13.25"/>
  </joint>
  <link name="RR_hip">
    <visual>
      <origin rpy="0 0 3.141592653589793" xyz="0 0 0"/>
      <!-- <origin rpy="${pi} ${pi} 0" xyz="0 0 0"/> -->
      <geometry>
        <mesh filename="../mesh_ngergo/FL_hip_link.STL" scale="1 1 1"/>
      </geometry>
      <material name="white"/>
    </visual>
    
    <inertial>
      <origin rpy="0 0 0" xyz="0.00181499 -0.00647781 -6.314e-05"/>
      <mass value="0.45381624"/>
      <inertia ixx="0.00033634" ixy="-9.86e-06" ixz="6.5e-07" iyy="0.0002604" iyz="-1.26e-06" izz="0.00036201"/>
    </inertial>
  </link>
  <joint name="RR_thigh_joint" type="revolute">
    <!-- c -->
    <!-- <origin rpy="0 0 0" xyz="0 ${thigh_offset*mirror} 0"/> -->
    <origin rpy="0 0.0 0" xyz="0 -0.1034 0"/>
    <parent link="RR_hip"/>
    <child link="RR_thigh"/>
    <!-- <axis xyz="0 -1 0"/> -->
    <axis xyz="0 1 0"/>
    <dynamics damping="0.0" friction="0.0"/>
    <limit effort="20" lower="-1" upper="2.64" velocity="13.25"/>
  </joint>
  <link name="RR_thigh">
    <visual>
      <origin rpy="0 0 0" xyz="0 0 0"/>
      <geometry>
        <mesh filename="../mesh_ngergo/FR_thigh_link.STL" scale="1 1 1"/>
      </geometry>
      <material name="white"/>
    </visual>
    <collision>
      <origin rpy="0 1.5707963267948966 0" xyz="0 0 -0.07511"/>
      <!-- <origin rpy="0 ${pi/2.0+0.1} 0" xyz="0 0 ${-thigh_length/2.0}"/> -->
      <geometry>
        <box size="0.15022 0.03 0.03"/>
      </geometry>
    </collision>
    
    <inertial>
      <origin rpy="0 0 0" xyz="-0.00256023 0.02066587 -0.01932269"/>
      <mass value="0.71506207"/>
      <inertia ixx="0.00189952" ixy="-4.028e-05" ixz="-0.00011453" iyy="0.00162545" iyz="-0.0002761" izz="0.00071971"/>
    </inertial>
  </link>
  <joint name="RR_calf_joint" type="revolute">
    <!-- cc -->
    <origin rpy="0 0 0" xyz="0 0 -0.15022"/>
    <parent link="RR_thigh"/>
    <child link="RR_calf"/>
    <axis xyz="0 1 0"/>
    <dynamics damping="0.0" friction="0.0"/>
    <limit effort="20" lower="-2.64" upper="-0.5" velocity="13.25"/>
  </joint>
  <link name="RR_calf">
    <visual>
      <origin rpy="0 0 0" xyz="0 0 0"/>
      <geometry>
        <mesh filename="../mesh_ngergo/FR_calf_link.STL" scale="1 1 1"/>
      </geometry>
      <material name="red"/>
    </visual>
    <collision>
      <origin rpy="0 1.5707963267948966 0" xyz="0 0 -0.074965"/>
      <geometry>
        <box size="0.14993 0.018 0.015"/>
      </geometry>
    </collision>
    <inertial>
      <origin rpy="0 0 0" xyz="0.00311164 -0.00026025 -0.0875749"/>
      <mass value="0.1160051"/>
      <inertia ixx="0.00036493" ixy="-6e-08" ixz="7.1e-07" iyy="0.00036973" iyz="2.97e-06" izz="2.582e-05"/>
    </inertial>
  </link>
  <joint name="RR_foot_fixed" type="fixed" dont_collapse="true">
    <origin rpy="0 0 0" xyz="0 0 -0.14993"/>
    <parent link="RR_calf"/>
    <child link="RR_foot"/>
  </joint>
  <link name="RR_foot">
    <visual>
      <origin rpy="0 0 0" xyz="0 0 0"/>
      <geometry>
        <sphere radius="0.02249"/>
        <!-- <mesh filename="package://legged_ngergo_description/meshes/$(arg robot_type)/FL_toe_link.STL" scale="1 1 1"/> -->
      </geometry>
      <material name="white"/>
    </visual>
    <collision>
      <origin rpy="0 0 0" xyz="0 0 0"/>
      <geometry>
        <sphere radius="0.02249"/>
      </geometry>
    </collision>
    <inertial>
      <mass value="0.05"/>
      <inertia ixx="1.0116002e-05" ixy="0.0" ixz="0.0" iyy="1.0116002e-05" iyz="0.0" izz="1.0116002e-05"/>
    </inertial>
  </link>
  
  <joint name="RL_hip_joint" type="revolute">
    <origin rpy="0 0 0" xyz="-0.17185 0.0436 -0.0"/>
    <parent link="base"/>
    <child link="RL_hip"/>
    <axis xyz="1 0 0"/>
    <dynamics damping="0.0" friction="0.0"/>
    <limit effort="20" lower="-0.34" upper="0.34" velocity="13.25"/>
  </joint>
  <link name="RL_hip">
    <visual>
      <origin rpy="0 0 3.141592653589793" xyz="0 0 0"/>
      <!-- <origin rpy="0 ${pi} 0" xyz="0 0 0"/> -->
      <geometry>
        <mesh filename="../mesh_ngergo/FR_hip_link.STL" scale="1 1 1"/>
      </geometry>
      <material name="white"/>
    </visual>
    
    <inertial>
      <origin rpy="0 0 0" xyz="0.00181499 0.00647781 -6.314e-05"/>
      <mass value="0.45381624"/>
      <inertia ixx="0.00033634" ixy="9.86e-06" ixz="6.5e-07" iyy="0.0002604" iyz="1.26e-06" izz="0.00036201"/>
    </inertial>
  </link>
  <joint name="RL_thigh_joint" type="revolute">
    <!-- c -->
    <!-- <origin rpy="0 0 0" xyz="0 ${thigh_offset*mirror} 0"/> -->
    <origin rpy="0 0.0 0" xyz="0 0.1034 0"/>
    <parent link="RL_hip"/>
    <child link="RL_thigh"/>
    <!-- <axis xyz="0 -1 0"/> -->
    <axis xyz="0 1 0"/>
    <dynamics damping="0.0" friction="0.0"/>
    <limit effort="20" lower="-1" upper="2.64" velocity="13.25"/>
  </joint>
  <link name="RL_thigh">
    <visual>
      <origin rpy="0 0 0" xyz="0 0 0"/>
      <geometry>
        <mesh filename="../mesh_ngergo/FL_thigh_link.STL" scale="1 1 1"/>
      </geometry>
      <material name="white"/>
    </visual>
    <collision>
      <origin rpy="0 1.5707963267948966 0" xyz="0 0 -0.07511"/>
      <geometry>
        <box size="0.15022 0.03 0.03"/>
      </geometry>
    </collision>
    
    <inertial>
      <origin rpy="0 0 0" xyz="-0.00256023 -0.02066587 -0.01932269"/>
      <mass value="0.71506207"/>
      <inertia ixx="0.00189952" ixy="4.028e-05" ixz="-0.00011453" iyy="0.00162545" iyz="0.0002761" izz="0.00071971"/>
    </inertial>
  </link>
  <joint name="RL_calf_joint" type="revolute">
    <!-- cc -->
    <origin rpy="0 0 0" xyz="0 0 -0.15022"/>
    <parent link="RL_thigh"/>
    <child link="RL_calf"/>
    <axis xyz="0 1 0"/>
    <dynamics damping="0.0" friction="0.0"/>
    <limit effort="20" lower="-2.64" upper="-0.5" velocity="13.25"/>
  </joint>
  <link name="RL_calf">
    <visual>
      <origin rpy="0 0 0" xyz="0 0 0"/>
      <geometry>
        <mesh filename="../mesh_ngergo/FL_calf_link.STL" scale="1 1 1"/>
      </geometry>
      <material name="red"/>
    </visual>
    <collision>
      <origin rpy="0 1.5707963267948966 0" xyz="0 0 -0.074965"/>
      <geometry>
        <box size="0.14993 0.018 0.015"/>
      </geometry>
    </collision>
    <inertial>
      <origin rpy="0 0 0" xyz="0.00311164 -0.00026025 -0.0875749"/>
      <mass value="0.1160051"/>
      <inertia ixx="0.00036493" ixy="-6e-08" ixz="7.1e-07" iyy="0.00036973" iyz="2.97e-06" izz="2.582e-05"/>
    </inertial>
  </link>
  <joint name="RL_foot_fixed" type="fixed" dont_collapse="true">
    <origin rpy="0 0 0" xyz="0 0 -0.14993"/>
    <parent link="RL_calf"/>
    <child link="RL_foot"/>
  </joint>
  <link name="RL_foot">
    <visual>
      <origin rpy="0 0 0" xyz="0 0 0"/>
      <geometry>
        <sphere radius="0.02249"/>
        <!-- <mesh filename="package://legged_ngergo_description/meshes/$(arg robot_type)/FL_toe_link.STL" scale="1 1 1"/> -->
      </geometry>
      <material name="white"/>
    </visual>
    <collision>
      <origin rpy="0 0 0" xyz="0 0 0"/>
      <geometry>
        <sphere radius="0.02249"/>
      </geometry>
    </collision>
    
    <inertial>
      <mass value="0.05"/>
      <inertia ixx="1.0116002e-05" ixy="0.0" ixz="0.0" iyy="1.0116002e-05" iyz="0.0" izz="1.0116002e-05"/>
    </inertial>
  </link>
  
</robot>
