<?xml version="1.0" ?>
<!-- =================================================================================== -->
<!-- |    This document was autogenerated by xacro from robot.xacro                    | -->
<!-- |    EDITING THIS FILE BY HAND IS NOT RECOMMENDED                                 | -->
<!-- =================================================================================== -->
<robot name="robot">
  <material name="black">
    <color rgba="0.0 0.0 0.0 1.0"/>
  </material>
  <material name="blue">
    <color rgba="0.0 0.0 0.8 1.0"/>
  </material>
  <material name="green">
    <color rgba="0.0 0.8 0.0 1.0"/>
  </material>
  <material name="gold">
    <color rgba="0.94901960784 0.75294117647 0.33725490196 0.0"/> 
  </material>
  <material name="grey">
    <color rgba="0.2 0.2 0.2 1.0"/>
  </material>
  <material name="silver">
    <color rgba="0.9137254901960784 0.9137254901960784 0.8470588235294118 1.0"/>
  </material>
  <material name="orange">
    <color rgba="1.0 0.4235294117647059 0.0392156862745098 1.0"/>
  </material>
  <material name="brown">
    <color rgba="0.8705882352941177 0.8117647058823529 0.7647058823529411 1.0"/>
  </material>
  <material name="red">
  <!-- aa0505 -->
    <!--color rgba="0.66666666667 0.01960784314 0.01960784314 1.0"/-->
    <color rgba="0.54901960784 0.04705882353 0.0431372549  1.0"/>
  </material>
  <material name="white">
    <color rgba="1.0 1.0 1.0 1.0"/>
  </material>
  
  <link name="base">
    <visual>
      <origin rpy="0 0 0" xyz="0 0 0"/>
      <geometry>
        <mesh filename="../meshes_ysc2go/trunk.STL" scale="1 1 1"/>
      </geometry>
      <material name="red"/>
    </visual>
    <collision>
      <origin rpy="0 0 0" xyz="0 0 0"/>
      <geometry>
        <box size="0.226 0.184 0.129"/>
      </geometry>
    </collision>
    <inertial>
      <origin rpy="0 0 0" xyz="0.03405506 -0.00027342 0.02745369"/>
      <!-- <origin rpy="0 0 0" xyz="0.055506 -0.00027342 0.02745369"/> -->
      <!-- <mesh filename="package://legged_ysc2go_description/meshes/$(arg robot_type)/trunk.STL" scale="1 1 1"/> -->
      <mass value="7.39662602"/>
      <inertia ixx="0.05468948" ixy="-9.577e-05" ixz="-0.02595783" iyy="0.14263652" iyz="-1.269e-05" izz="0.11906457"/>
    </inertial>
  </link>
  <!-- Imu is fixed to the base link -->
  <joint name="unitree_imu_joint" type="fixed">
    <origin rpy="0. 0. 0." xyz="0. 0. 0."/>
    <parent link="base"/>
    <child link="unitree_imu"/>
  </joint>
  <!-- Imu link -->
  <link name="unitree_imu">
    <inertial>
      <mass value="0.01"/>
      <origin rpy="0 0 0" xyz="0 0 0"/>
      <inertia ixx="0.000001" ixy="0" ixz="0" iyy="0.000001" iyz="0" izz="0.000001"/>
    </inertial>
    <visual>
      <origin rpy="0 0 0" xyz="0 0 0"/>
      <geometry>
        <box size="0.015 0.015 0.004"/>
      </geometry>
    </visual>
    <material name="orange">
      <color rgba="255 108 10 255"/>
    </material>
  </link>
  
  <joint name="FR_hip_joint" type="revolute">
    <origin rpy="0 0 0" xyz="0.185 -0.045 0.0"/>
    <parent link="base"/>
    <child link="FR_hip"/>
    <axis xyz="1 0 0"/>
    <dynamics damping="0.0" friction="0.0"/>
    <!-- <limit effort="19.94" lower="-0.45" upper="0.45" velocity="30.9971"/> -->
      <limit effort="19.94" lower="-0.35" upper="0.35" velocity="30.9971"/>
  </joint>
  <link name="FR_hip">
    <visual>
      <origin rpy="0 0 0" xyz="0 0 0"/>
      <!-- <origin rpy="${pi} 0 0" xyz="0 0 0"/> -->
      <geometry>
        <mesh filename="../meshes_ysc2go/FR_hip_link.STL" scale="1 1 1"/>
      </geometry>
      <material name="white"/>
    </visual>
    <!-- <collision>
      <origin rpy="1.5707963267948966 0 0" xyz="0 0 0"/>
      <geometry>
        <cylinder length="0.032" radius="0.035"/>
      </geometry>
    </collision> -->
    <inertial>
      <origin rpy="0 0 0" xyz="-0.0028174 -0.00258054 5.131e-05"/>
      <mass value="0.55682085"/>
      <inertia ixx="0.000301" ixy="-1.589e-05" ixz="-2.2e-07" iyy="0.0003762" iyz="-9.8e-07" izz="0.00035095"/>
    </inertial>
  </link>
  <joint name="FR_thigh_joint" type="revolute">
    <!-- c -->
    <!-- <origin rpy="0 0 0" xyz="0 ${thigh_offset*mirror} 0"/> -->
    <origin rpy="0 0.0 0" xyz="0 -0.10879 0"/>
    <parent link="FR_hip"/>
    <child link="FR_thigh"/>
    <!-- <axis xyz="0 -1 0"/> -->
    <axis xyz="0 1 0"/>
    <dynamics damping="0.0" friction="0.0"/>
    <limit effort="19.94" lower="-1" upper="2.64" velocity="30.9971"/>
  </joint>
  <link name="FR_thigh">
    <visual>
      <origin rpy="0 0 0" xyz="0 0 0"/>
      <geometry>
        <mesh filename="../meshes_ysc2go/FR_thigh_link.STL" scale="1 1 1"/>
      </geometry>
      <material name="white"/>
    </visual>
    <collision>
      <origin rpy="0 1.5707963267948966 0" xyz="0 0 -0.09"/>
      <geometry>
        <box size="0.18 0.03 0.03"/>
      </geometry>
    </collision>
    <!-- <collision>
      <origin rpy="1.5707963267948966 0 0" xyz="0 0 0"/>
      <geometry>
        <cylinder length="0.035" radius="0.035"/>
      </geometry>
    </collision> -->
    <inertial>
      <origin rpy="0 0 0" xyz="-0.00325856 0.02292409 -0.02434837"/>
      <mass value="1.05578211"/>
      <inertia ixx="0.00385729" ixy="-8.335e-05" ixz="-0.00024918" iyy="0.00360924" iyz="-0.00057929" izz="0.00124018"/>
    </inertial>
  </link>
  <joint name="FR_calf_joint" type="revolute">
    <!-- cc -->
    <origin rpy="0 0 0" xyz="0 0 -0.18"/>
    <parent link="FR_thigh"/>
    <child link="FR_calf"/>
    <axis xyz="0 1 0"/>
    <dynamics damping="0.0" friction="0.0"/>
    <limit effort="19.94" lower="-2.64" upper="-0.5" velocity="30.9971"/>
  </joint>
  <link name="FR_calf">
    <visual>
      <origin rpy="0 0 0" xyz="0 0 0"/>
      <geometry>
        <mesh filename="../meshes_ysc2go/FR_calf_link.STL" scale="1 1 1"/>
      </geometry>
      <material name="red"/>
    </visual>
    <collision>
      <origin rpy="0 1.5707963267948966 0" xyz="0 0 -0.09"/>
      <geometry>
        <box size="0.18 0.018 0.015"/>
      </geometry>
    </collision>
    <inertial>
      <origin rpy="0 0 0" xyz="0.00207601 0.00020335 -0.10653136"/>
      <mass value="0.2749309"/>
      <inertia ixx="0.00142334" ixy="-2.7e-07" ixz="4.8e-07" iyy="0.0014332" iyz="-1.04e-06" izz="7.192e-05"/>
    </inertial>
  </link>
  <joint name="FR_foot_fixed" type="fixed" dont_collapse="true">
    <origin rpy="0 0 0" xyz="0 0 -0.18"/>
    <parent link="FR_calf"/>
    <child link="FR_foot"/>
  </joint>
  <link name="FR_foot">
    <visual>
      <origin rpy="0 0 0" xyz="0 0 0"/>
      <geometry>
        <sphere radius="0.02169"/>
        <!-- <mesh filename="package://legged_ysc2go_description/meshes/$(arg robot_type)/FL_toe_link.STL" scale="1 1 1"/> -->
      </geometry>
      <material name="white"/>
    </visual>
    <collision>
      <origin rpy="0 0 0" xyz="0 0 0"/>
      <geometry>
        <sphere radius="0.02169"/>
      </geometry>
    </collision>
    <inertial>
      <mass value="0.05"/>
      <inertia ixx="9.409122000000001e-06" ixy="0.0" ixz="0.0" iyy="9.409122000000001e-06" iyz="0.0" izz="9.409122000000001e-06"/>
    </inertial>
   
  </link>
  
  <joint name="FL_hip_joint" type="revolute">
    <origin rpy="0 0 0" xyz="0.185 0.045 0.0"/>
    <parent link="base"/>
    <child link="FL_hip"/>
    <axis xyz="1 0 0"/>
    <dynamics damping="0.0" friction="0.0"/>
    <limit effort="19.94" lower="-0.35" upper="0.35" velocity="30.9971"/>
  </joint>
  <link name="FL_hip">
    <visual>
      <origin rpy="0 0 0" xyz="0 0 0"/>
      <geometry>
        <mesh filename="../meshes_ysc2go/FL_hip_link.STL" scale="1 1 1"/>
      </geometry>
      <material name="white"/>
    </visual>
    <!-- <collision>
      <origin rpy="1.5707963267948966 0 0" xyz="0 0 0"/>
      <geometry>
        <cylinder length="0.032" radius="0.035"/>
      </geometry>
    </collision> -->
    <inertial>
      <origin rpy="0 0 0" xyz="-0.0028174 0.00258054 5.131e-05"/>
      <mass value="0.55682085"/>
      <inertia ixx="0.000301" ixy="1.589e-05" ixz="-2.2e-07" iyy="0.0003762" iyz="9.8e-07" izz="0.00035095"/>
    </inertial>
  </link>
  <joint name="FL_thigh_joint" type="revolute">
    <!-- c -->
    <!-- <origin rpy="0 0 0" xyz="0 ${thigh_offset*mirror} 0"/> -->
    <origin rpy="0 0.0 0" xyz="0 0.10879 0"/>
    <parent link="FL_hip"/>
    <child link="FL_thigh"/>
    <!-- <axis xyz="0 -1 0"/> -->
    <axis xyz="0 1 0"/>
    <dynamics damping="0.0" friction="0.0"/>
    <limit effort="19.94" lower="-1" upper="2.64" velocity="30.9971"/>
  </joint>
  <link name="FL_thigh">
    <visual>
      <origin rpy="0 0 0" xyz="0 0 0"/>
      <geometry>
        <mesh filename="../meshes_ysc2go/FL_thigh_link.STL" scale="1 1 1"/>
      </geometry>
      <material name="white"/>
    </visual>
    <collision>
      <origin rpy="0 1.5707963267948966 0" xyz="0 0 -0.09"/>
      <geometry>
        <box size="0.18 0.03 0.03"/>
      </geometry>
    </collision>
    <!-- <collision>
      <origin rpy="1.5707963267948966 0 0" xyz="0 0 0"/>
      <geometry>
        <cylinder length="0.035" radius="0.035"/>
      </geometry>
    </collision> -->
    <inertial>
      <origin rpy="0 0 0" xyz="-0.00325856 -0.02292409 -0.02434837"/>
      <mass value="1.05578211"/>
      <inertia ixx="0.00385729" ixy="8.335e-05" ixz="-0.00024918" iyy="0.00360924" iyz="0.00057929" izz="0.00124018"/>
    </inertial>
  </link>
  <joint name="FL_calf_joint" type="revolute">
    <!-- cc -->
    <origin rpy="0 0 0" xyz="0 0 -0.18"/>
    <parent link="FL_thigh"/>
    <child link="FL_calf"/>
    <axis xyz="0 1 0"/>
    <dynamics damping="0.0" friction="0.0"/>
    <limit effort="19.94" lower="-2.64" upper="-0.5" velocity="30.9971"/>
  </joint>
  <link name="FL_calf">
    <visual>
      <origin rpy="0 0 0" xyz="0 0 0"/>
      <geometry>
        <mesh filename="../meshes_ysc2go/FL_calf_link.STL" scale="1 1 1"/>
      </geometry>
      <material name="red"/>
    </visual>
    <collision>
      <origin rpy="0 1.5707963267948966 0" xyz="0 0 -0.09"/>
      <geometry>
        <box size="0.18 0.018 0.015"/>
      </geometry>
    </collision>
    <inertial>
      <origin rpy="0 0 0" xyz="0.00207601 0.00020335 -0.10653136"/>
      <mass value="0.2749309"/>
      <inertia ixx="0.00142334" ixy="-2.7e-07" ixz="4.8e-07" iyy="0.0014332" iyz="-1.04e-06" izz="7.192e-05"/>
    </inertial>
  </link>
  <joint name="FL_foot_fixed" type="fixed" dont_collapse="true">
    <origin rpy="0 0 0" xyz="0 0 -0.18"/>
    <parent link="FL_calf"/>
    <child link="FL_foot"/>
  </joint>
  <link name="FL_foot">
    <visual>
      <origin rpy="0 0 0" xyz="0 0 0"/>
      <geometry>
        <sphere radius="0.02169"/>
        <!-- <mesh filename="package://legged_ysc2go_description/meshes/$(arg robot_type)/FL_toe_link.STL" scale="1 1 1"/> -->
      </geometry>
      <material name="white"/>
    </visual>
    <collision>
      <origin rpy="0 0 0" xyz="0 0 0"/>
      <geometry>
        <sphere radius="0.02169"/>
      </geometry>
    </collision>
    <inertial>
      <mass value="0.05"/>
      <inertia ixx="9.409122000000001e-06" ixy="0.0" ixz="0.0" iyy="9.409122000000001e-06" iyz="0.0" izz="9.409122000000001e-06"/>
    </inertial>
    
  </link>
 
  <joint name="RR_hip_joint" type="revolute">
    <origin rpy="0 0 0" xyz="-0.185 -0.045 0.0"/>
    <parent link="base"/>
    <child link="RR_hip"/>
    <axis xyz="1 0 0"/>
    <dynamics damping="0.0" friction="0.0"/>
    <limit effort="19.94" lower="-0.35" upper="0.35" velocity="30.9971"/>
  </joint>
  <link name="RR_hip">
    <visual>
      <origin rpy="0 0 3.141592653589793" xyz="0 0 0"/>
      <geometry>
        <mesh filename="../meshes_ysc2go/FL_hip_link.STL" scale="1 1 1"/>
      </geometry>
      <material name="white"/>
    </visual>
    <!-- <collision>
      <origin rpy="1.5707963267948966 0 0" xyz="0 0 0"/>
      <geometry>
        <cylinder length="0.032" radius="0.035"/>
      </geometry>
    </collision> -->
    <inertial>
      <origin rpy="0 0 0" xyz="0.0028174 -0.00258054 5.131e-05"/>
      <mass value="0.55682085"/>
      <inertia ixx="0.000301" ixy="1.589e-05" ixz="2.2e-07" iyy="0.0003762" iyz="-9.8e-07" izz="0.00035095"/>
    </inertial>
  </link>
  <joint name="RR_thigh_joint" type="revolute">
    <!-- c -->
    <!-- <origin rpy="0 0 0" xyz="0 ${thigh_offset*mirror} 0"/> -->
    <origin rpy="0 0.0 0" xyz="0 -0.10879 0"/>
    <parent link="RR_hip"/>
    <child link="RR_thigh"/>
    <!-- <axis xyz="0 -1 0"/> -->
    <axis xyz="0 1 0"/>
    <dynamics damping="0.0" friction="0.0"/>
    <limit effort="19.94" lower="-1" upper="2.64" velocity="30.9971"/>
  </joint>
  <link name="RR_thigh">
    <visual>
      <origin rpy="0 0 0" xyz="0 0 0"/>
      <geometry>
        <mesh filename="../meshes_ysc2go/FR_thigh_link.STL" scale="1 1 1"/>
      </geometry>
      <material name="white"/>
    </visual>
    <collision>
      <origin rpy="0 1.5707963267948966 0" xyz="0 0 -0.09"/>
      <geometry>
        <box size="0.18 0.03 0.03"/>
      </geometry>
    </collision>
    <!-- <collision>
      <origin rpy="1.5707963267948966 0 0" xyz="0 0 0"/>
      <geometry>
        <cylinder length="0.035" radius="0.035"/>
      </geometry>
    </collision> -->
    <inertial>
      <origin rpy="0 0 0" xyz="-0.00325856 0.02292409 -0.02434837"/>
      <mass value="1.05578211"/>
      <inertia ixx="0.00385729" ixy="-8.335e-05" ixz="-0.00024918" iyy="0.00360924" iyz="-0.00057929" izz="0.00124018"/>
    </inertial>
  </link>
  <joint name="RR_calf_joint" type="revolute">
    <!-- cc -->
    <origin rpy="0 0 0" xyz="0 0 -0.18"/>
    <parent link="RR_thigh"/>
    <child link="RR_calf"/>
    <axis xyz="0 1 0"/>
    <dynamics damping="0.0" friction="0.0"/>
    <limit effort="19.94" lower="-2.64" upper="-0.5" velocity="30.9971"/>
  </joint>
  <link name="RR_calf">
    <visual>
      <origin rpy="0 0 0" xyz="0 0 0"/>
      <geometry>
        <mesh filename="../meshes_ysc2go/FR_calf_link.STL" scale="1 1 1"/>
      </geometry>
      <material name="red"/>
    </visual>
    <collision>
      <origin rpy="0 1.5707963267948966 0" xyz="0 0 -0.09"/>
      <geometry>
        <box size="0.18 0.018 0.015"/>
      </geometry>
    </collision>
    <inertial>
      <origin rpy="0 0 0" xyz="0.00207601 0.00020335 -0.10653136"/>
      <mass value="0.2749309"/>
      <inertia ixx="0.00142334" ixy="-2.7e-07" ixz="4.8e-07" iyy="0.0014332" iyz="-1.04e-06" izz="7.192e-05"/>
    </inertial>
  </link>
  <joint name="RR_foot_fixed" type="fixed" dont_collapse="true">
    <origin rpy="0 0 0" xyz="0 0 -0.18"/>
    <parent link="RR_calf"/>
    <child link="RR_foot"/>
  </joint>
  <link name="RR_foot">
    <visual>
      <origin rpy="0 0 0" xyz="0 0 0"/>
      <geometry>
        <sphere radius="0.02169"/>
        <!-- <mesh filename="package://legged_ysc2go_description/meshes/$(arg robot_type)/FL_toe_link.STL" scale="1 1 1"/> -->
      </geometry>
      <material name="white"/>
    </visual>
    <collision>
      <origin rpy="0 0 0" xyz="0 0 0"/>
      <geometry>
        <sphere radius="0.02169"/>
      </geometry>
    </collision>
    <inertial>
      <mass value="0.05"/>
      <inertia ixx="9.409122000000001e-06" ixy="0.0" ixz="0.0" iyy="9.409122000000001e-06" iyz="0.0" izz="9.409122000000001e-06"/>
    </inertial>
    <!-- <inertial>
                <mass value="${0.0}"/>
                <inertia
                        ixx="0.0" ixy="0.0" ixz="0.0"
                        iyy="0.0" iyz="0.0"
                        izz="0.0"/>
            </inertial> -->
    <!-- <inertial>
                <mass value="${foot_mass}"/>
                <origin rpy="0 0 0" xyz="${foot_com_x} ${foot_com_y} ${foot_com_z}"/>
                <inertia
                        ixx="${foot_ixx}" ixy="${foot_ixy}" ixz="${foot_ixz}"
                        iyy="${foot_iyy}" iyz="${foot_iyz}"
                        izz="${foot_izz}"/>
            </inertial> -->
  </link>
  
  <joint name="RL_hip_joint" type="revolute">
    <origin rpy="0 0 0" xyz="-0.185 0.045 0.0"/>
    <parent link="base"/>
    <child link="RL_hip"/>
    <axis xyz="1 0 0"/>
    <dynamics damping="0.0" friction="0.0"/>
    <limit effort="19.94" lower="-0.35" upper="0.35" velocity="30.9971"/>
  </joint>
  <link name="RL_hip">
    <visual>
      <origin rpy="0 0 3.141592653589793" xyz="0 0 0"/>
      <geometry>
        <mesh filename="../meshes_ysc2go/FR_hip_link.STL" scale="1 1 1"/>
      </geometry>
      <material name="white"/>
    </visual>
    <!-- <collision>
      <origin rpy="1.5707963267948966 0 0" xyz="0 0 0"/>
      <geometry>
        <cylinder length="0.032" radius="0.035"/>
      </geometry>
    </collision> -->
    <inertial>
      <origin rpy="0 0 0" xyz="0.0028174 0.00258054 5.131e-05"/>
      <mass value="0.55682085"/>
      <inertia ixx="0.000301" ixy="-1.589e-05" ixz="2.2e-07" iyy="0.0003762" iyz="9.8e-07" izz="0.00035095"/>
    </inertial>
  </link>
  <joint name="RL_thigh_joint" type="revolute">
    <!-- c -->
    <!-- <origin rpy="0 0 0" xyz="0 ${thigh_offset*mirror} 0"/> -->
    <origin rpy="0 0.0 0" xyz="0 0.10879 0"/>
    <parent link="RL_hip"/>
    <child link="RL_thigh"/>
    <!-- <axis xyz="0 -1 0"/> -->
    <axis xyz="0 1 0"/>
    <dynamics damping="0.0" friction="0.0"/>
    <limit effort="19.94" lower="-1" upper="2.64" velocity="30.9971"/>
  </joint>
  <link name="RL_thigh">
    <visual>
      <origin rpy="0 0 0" xyz="0 0 0"/>
      <geometry>
        <mesh filename="../meshes_ysc2go/FL_thigh_link.STL" scale="1 1 1"/>
      </geometry>
      <material name="white"/>
    </visual>
    <collision>
      <origin rpy="0 1.5707963267948966 0" xyz="0 0 -0.09"/>
      <geometry>
        <box size="0.18 0.03 0.03"/>
      </geometry>
    </collision>
    <!-- <collision>
      <origin rpy="1.5707963267948966 0 0" xyz="0 0 0"/>
      <geometry>
        <cylinder length="0.035" radius="0.035"/>
      </geometry>
    </collision> -->
    <inertial>
      <origin rpy="0 0 0" xyz="-0.00325856 -0.02292409 -0.02434837"/>
      <mass value="1.05578211"/>
      <inertia ixx="0.00385729" ixy="8.335e-05" ixz="-0.00024918" iyy="0.00360924" iyz="0.00057929" izz="0.00124018"/>
    </inertial>
  </link>
  <joint name="RL_calf_joint" type="revolute">
    <!-- cc -->
    <origin rpy="0 0 0" xyz="0 0 -0.18"/>
    <parent link="RL_thigh"/>
    <child link="RL_calf"/>
    <axis xyz="0 1 0"/>
    <dynamics damping="0.0" friction="0.0"/>
    <limit effort="19.94" lower="-2.64" upper="-0.5" velocity="30.9971"/>
  </joint>
  <link name="RL_calf">
    <visual>
      <origin rpy="0 0 0" xyz="0 0 0"/>
      <geometry>
        <mesh filename="../meshes_ysc2go/FL_calf_link.STL" scale="1 1 1"/>
      </geometry>
      <material name="red"/>
    </visual>
    <collision>
      <origin rpy="0 1.5707963267948966 0" xyz="0 0 -0.09"/>
      <geometry>
        <box size="0.18 0.018 0.015"/>
      </geometry>
    </collision>
    <inertial>
      <origin rpy="0 0 0" xyz="0.00207601 0.00020335 -0.10653136"/>
      <mass value="0.2749309"/>
      <inertia ixx="0.00142334" ixy="-2.7e-07" ixz="4.8e-07" iyy="0.0014332" iyz="-1.04e-06" izz="7.192e-05"/>
    </inertial>
  </link>
  <joint name="RL_foot_fixed" type="fixed" dont_collapse="true">
    <origin rpy="0 0 0" xyz="0 0 -0.18"/>
    <parent link="RL_calf"/>
    <child link="RL_foot"/>
  </joint>
  <link name="RL_foot">
    <visual>
      <origin rpy="0 0 0" xyz="0 0 0"/>
      <geometry>
        <sphere radius="0.02169"/>
        <!-- <mesh filename="package://legged_ysc2go_description/meshes/$(arg robot_type)/FL_toe_link.STL" scale="1 1 1"/> -->
      </geometry>
      <material name="white"/>
    </visual>
    <collision>
      <origin rpy="0 0 0" xyz="0 0 0"/>
      <geometry>
        <sphere radius="0.02169"/>
      </geometry>
    </collision>
    <inertial>
      <mass value="0.05"/>
      <inertia ixx="9.409122000000001e-06" ixy="0.0" ixz="0.0" iyy="9.409122000000001e-06" iyz="0.0" izz="9.409122000000001e-06"/>
    </inertial>
    <!-- <inertial>
                <mass value="${0.0}"/>
                <inertia
                        ixx="0.0" ixy="0.0" ixz="0.0"
                        iyy="0.0" iyz="0.0"
                        izz="0.0"/>
            </inertial> -->
    <!-- <inertial>
                <mass value="${foot_mass}"/>
                <origin rpy="0 0 0" xyz="${foot_com_x} ${foot_com_y} ${foot_com_z}"/>
                <inertia
                        ixx="${foot_ixx}" ixy="${foot_ixy}" ixz="${foot_ixz}"
                        iyy="${foot_iyy}" iyz="${foot_iyz}"
                        izz="${foot_izz}"/>
            </inertial> -->
  </link>
  
  <!-- Robot Footprint -->
  <!-- <joint name="footprint_joint" type="fixed">
        <parent link="base"/>
        <child link="base_footprint"/>
        <origin xyz="0.0 0.0 -0.2" rpy="0 0 0"/>
    </joint>

    <link name="base_footprint">
      <inertial>
      <origin xyz="0 0 0" rpy="${pi/2} 0 ${pi/2}"/>      
      <mass value="0.001"/>
      <inertia ixx="0.0" ixy="0.0" ixz="0.0" iyy="0.0" iyz="0.0" izz="0.0"/>
    </inertial>
    </link>

    <xacro:lidar parent="base" xyz="-0.065 0. 0.1" rpy="0. 0. 0."/> -->
 
  <!-- This link is only for head collision -->
  <joint name="head_joint" type="fixed">
    <parent link="base"/>
    <child link="head"/>
    <origin rpy="0 0 0" xyz="0 0 0"/>
  </joint>
  <link name="head">
    <collision>
      <origin rpy="0 0 0" xyz="0.256 0 0.120"/>
      <geometry>
        <box size="0.076 0.060 0.040"/>
      </geometry>
    </collision>
    <collision>
      <origin rpy="0 0 0" xyz="0.225 0 0.150"/>
      <geometry>
        <box size="0.020 0.080 0.100"/>
      </geometry>
    </collision>
  </link>
</robot>

