<?xml version="1.0" ?>
<!-- =================================================================================== -->
<!-- |    This document was autogenerated by xacro from /home/gsmp/01_project/arsoft_control/src/legged_control/legged_control/legged_examples/legged_xxgo/legged_xxgo_description/urdf/robot.xacro | -->
<!-- |    EDITING THIS FILE BY HAND IS NOT RECOMMENDED                                 | -->
<!-- =================================================================================== -->
<robot name="robot">
  <material name="black">
    <color rgba="0.0 0.0 0.0 1.0"/>
  </material>
  <material name="blue">
    <color rgba="0.0 0.0 0.8 1.0"/>
  </material>
  <material name="green">
    <color rgba="0.0 0.8 0.0 1.0"/>
  </material>
  <material name="grey">
    <color rgba="0.2 0.2 0.2 1.0"/>
  </material>
  <material name="silver">
    <color rgba="0.9137254901960784 0.9137254901960784 0.8470588235294118 1.0"/>
  </material>
  <material name="orange">
    <color rgba="1.0 0.4235294117647059 0.0392156862745098 1.0"/>
  </material>
  <material name="brown">
    <color rgba="0.8705882352941177 0.8117647058823529 0.7647058823529411 1.0"/>
  </material>
  <material name="red">
    <color rgba="0.8 0.0 0.0 1.0"/>
  </material>
  <material name="white">
    <color rgba="1.0 1.0 1.0 1.0"/>
  </material>

  <link name="base">
    <visual>
      <origin rpy="0 0 0" xyz="0 0 0"/>
      <geometry>
        <mesh filename="../meshes/trunk.STL" scale="1 1 1"/>
      </geometry>
      <material name="white"/>
    </visual>
    <collision>
      <origin rpy="0 0 0" xyz="0 0 0"/>
      <geometry>
        <box size="0.238 0.18 0.14"/>
      </geometry>
    </collision>
    <inertial>
      <origin rpy="0 0 0" xyz="-0.02248608 -0.00011879 -0.00679147"/>
      <mass value="4.1430459"/>
      <inertia ixx="0.01454145" ixy="0.00017282" ixz="-0.00014576" iyy="0.02842016" iyz="4.241e-05" izz="0.03523081"/>
    </inertial>
  </link>
  <!-- Imu is fixed to the base link -->
  <joint name="base_imu_joint" type="fixed">
    <origin rpy="0. 0. 0." xyz="0. 0. 0."/>
    <parent link="base"/>
    <child link="base_imu"/>
  </joint>
  <!-- Imu link -->
  <link name="base_imu">
    <inertial>
      <mass value="0.01"/>
      <origin rpy="0 0 0" xyz="0 0 0"/>
      <inertia ixx="0.000001" ixy="0" ixz="0" iyy="0.000001" iyz="0" izz="0.000001"/>
    </inertial>
    <visual>
      <origin rpy="0 0 0" xyz="0 0 0"/>
      <geometry>
        <box size="0.015 0.015 0.004"/>
      </geometry>
    </visual>
    <material name="orange">
      <color rgba="255 108 10 255"/>
    </material>
  </link>

  <joint name="FR_hip_joint" type="revolute">
    <origin rpy="0 0 0" xyz="0.1645 -0.05 0.0"/>
    <parent link="base"/>
    <child link="FR_hip"/>
    <axis xyz="1 0 0"/>
    <dynamics damping="0.0" friction="0.2"/>
    <limit effort="12.0001" lower="-0.45" upper="0.45" velocity="30.9971"/>
  </joint>
  <link name="FR_hip">
    <visual>
      <origin rpy="0 0 0" xyz="0 0 0"/>
      <!-- <origin rpy="${pi} 0 0" xyz="0 0 0"/> -->
      <geometry>
        <mesh filename="../meshes/FR_hip_link.STL" scale="1 1 1"/>
      </geometry>
      <material name="white"/>
    </visual>
    <!-- <collision>
      <origin rpy="1.5707963267948966 0 0" xyz="0 0 0"/>
      <geometry>
        <cylinder length="0.032" radius="0.035"/>
      </geometry>
    </collision> -->
    <inertial>
      <origin rpy="0 0 0" xyz="-0.00351874 -0.00206525 -0.00048653"/>
      <mass value="0.3531958"/>
      <inertia ixx="0.00014315" ixy="1.5e-07" ixz="-4e-08" iyy="0.00026346" iyz="1.4e-07" izz="0.00017711"/>
    </inertial>
  </link>
  <joint name="FR_thigh_joint" type="revolute">
    <!-- c -->
    <!-- <origin rpy="0 0 0" xyz="0 ${thigh_offset*mirror} 0"/> -->
    <origin rpy="0 0.0 0" xyz="0 -0.08055 0"/>
    <parent link="FR_hip"/>
    <child link="FR_thigh"/>
    <!-- <axis xyz="0 -1 0"/> -->
    <axis xyz="0 1 0"/>
    <dynamics damping="0.0" friction="0.2"/>
    <limit effort="12.0001" lower="-1" upper="1.79" velocity="30.9971"/>
  </joint>
  <link name="FR_thigh">
    <visual>
      <origin rpy="0 0 0" xyz="0 0 0"/>
      <geometry>
        <mesh filename="../meshes/FR_thigh_link.STL" scale="1 1 1"/>
      </geometry>
      <material name="white"/>
    </visual>
    <collision>
      <origin rpy="0 1.5707963267948966 0" xyz="0 0 -0.06"/>
      <geometry>
        <box size="0.12 0.03 0.03"/>
      </geometry>
    </collision>
    <!-- <collision>
      <origin rpy="1.5707963267948966 0 0" xyz="0 0 0"/>
      <geometry>
        <cylinder length="0.035" radius="0.035"/>
      </geometry>
    </collision> -->
    <inertial>
      <origin rpy="0 0 0" xyz="-0.00371117 0.01697974 -0.01400046"/>
      <mass value="0.71774765"/>
      <inertia ixx="0.00144898" ixy="-5.716e-05" ixz="-0.00011203" iyy="0.00135146" iyz="-0.00019629" izz="0.00071909"/>
    </inertial>
  </link>
  <joint name="FR_calf_joint" type="revolute">
    <!-- cc -->
    <origin rpy="0 0 0" xyz="0 0 -0.12"/>
    <parent link="FR_thigh"/>
    <child link="FR_calf"/>
    <axis xyz="0 1 0"/>
    <dynamics damping="0.0" friction="0.2"/>
    <limit effort="12.0001" lower="-2.55" upper="-0.9" velocity="30.9971"/>
  </joint>
  <link name="FR_calf">
    <visual>
      <origin rpy="0 0 0" xyz="0 0 0"/>
      <geometry>
        <mesh filename="../meshes/FR_calf_link.STL" scale="1 1 1"/>
      </geometry>
      <material name="white"/>
    </visual>
    <collision>
      <origin rpy="0 1.5707963267948966 0" xyz="0 0 -0.08426"/>
      <geometry>
        <box size="0.16852 0.018 0.015"/>
      </geometry>
    </collision>
    <inertial>
      <origin rpy="0 0 0" xyz="5.074e-05 0.0001304 -0.09362007"/>
      <mass value="0.17146643"/>
      <inertia ixx="0.0008322" ixy="9e-08" ixz="3.836e-05" iyy="0.00083464" iyz="-2.18e-06" izz="3.316e-05"/>
    </inertial>
  </link>
  <joint name="FR_foot_fixed" type="fixed" dont_collapse="true">
    <origin rpy="0 0 0" xyz="0 0 -0.16852"/>
    <parent link="FR_calf"/>
    <child link="FR_foot"/>
  </joint>
  <link name="FR_foot">
    <visual>
      <origin rpy="0 0 0" xyz="0 0 0"/>
      <geometry>
        <sphere radius="0.023"/>
        <!-- <mesh filename="package://legged_xxgo_description/meshes/$(arg robot_type)/FL_toe_link.STL" scale="1 1 1"/> -->
      </geometry>
      <material name="white"/>
    </visual>
    <collision>
      <origin rpy="0 0 0" xyz="0 0 0"/>
      <geometry>
        <sphere radius="0.023"/>
      </geometry>
    </collision>
    <inertial>
      <mass value="0.05"/>
      <origin rpy="0 0 0" xyz="3.045e-05 0 -0.00104172"/>
      <inertia ixx="1.0579999999999999e-05" ixy="0.0" ixz="0.0" iyy="1.0579999999999999e-05" iyz="0.0" izz="1.0579999999999999e-05"/>
    </inertial>
    <!-- <inertial>
                <mass value="${0.0}"/>
                <inertia
                        ixx="0.0" ixy="0.0" ixz="0.0"
                        iyy="0.0" iyz="0.0"
                        izz="0.0"/>
            </inertial> -->
    <!-- <inertial>
                <mass value="${foot_mass}"/>
                <origin rpy="0 0 0" xyz="${foot_com_x} ${foot_com_y} ${foot_com_z}"/>
                <inertia
                        ixx="${foot_ixx}" ixy="${foot_ixy}" ixz="${foot_ixz}"
                        iyy="${foot_iyy}" iyz="${foot_iyz}"
                        izz="${foot_izz}"/>
            </inertial> -->
  </link>
  <joint name="FL_hip_joint" type="revolute">
    <origin rpy="0 0 0" xyz="0.1645 0.05 0.0"/>
    <parent link="base"/>
    <child link="FL_hip"/>
    <axis xyz="1 0 0"/>
    <dynamics damping="0.0" friction="0.2"/>
    <limit effort="12.0001" lower="-0.45" upper="0.45" velocity="30.9971"/>
  </joint>
  <link name="FL_hip">
    <visual>
      <origin rpy="0 0 0" xyz="0 0 0"/>
      <geometry>
        <mesh filename="../meshes/FL_hip_link.STL" scale="1 1 1"/>
      </geometry>
      <material name="white"/>
    </visual>
    <!-- <collision>
      <origin rpy="1.5707963267948966 0 0" xyz="0 0 0"/>
      <geometry>
        <cylinder length="0.032" radius="0.035"/>
      </geometry>
    </collision> -->
    <inertial>
      <origin rpy="0 0 0" xyz="-0.00351874 0.00206525 -0.00048653"/>
      <mass value="0.3531958"/>
      <inertia ixx="0.00014315" ixy="-1.5e-07" ixz="-4e-08" iyy="0.00026346" iyz="-1.4e-07" izz="0.00017711"/>
    </inertial>
  </link>
  <joint name="FL_thigh_joint" type="revolute">
    <!-- c -->
    <!-- <origin rpy="0 0 0" xyz="0 ${thigh_offset*mirror} 0"/> -->
    <origin rpy="0 0.0 0" xyz="0 0.08055 0"/>
    <parent link="FL_hip"/>
    <child link="FL_thigh"/>
    <!-- <axis xyz="0 -1 0"/> -->
    <axis xyz="0 1 0"/>
    <dynamics damping="0.0" friction="0.2"/>
    <limit effort="12.0001" lower="-1" upper="1.79" velocity="30.9971"/>
  </joint>
  <link name="FL_thigh">
    <visual>
      <origin rpy="0 0 0" xyz="0 0 0"/>
      <geometry>
        <mesh filename="../meshes/FL_thigh_link.STL" scale="1 1 1"/>
      </geometry>
      <material name="white"/>
    </visual>
    <collision>
      <origin rpy="0 1.5707963267948966 0" xyz="0 0 -0.06"/>
      <geometry>
        <box size="0.12 0.03 0.03"/>
      </geometry>
    </collision>
    <!-- <collision>
      <origin rpy="1.5707963267948966 0 0" xyz="0 0 0"/>
      <geometry>
        <cylinder length="0.035" radius="0.035"/>
      </geometry>
    </collision> -->
    <inertial>
      <origin rpy="0 0 0" xyz="-0.00371117 -0.01697974 -0.01400046"/>
      <mass value="0.71774765"/>
      <inertia ixx="0.00144898" ixy="5.716e-05" ixz="-0.00011203" iyy="0.00135146" iyz="0.00019629" izz="0.00071909"/>
    </inertial>
  </link>
  <joint name="FL_calf_joint" type="revolute">
    <!-- cc -->
    <origin rpy="0 0 0" xyz="0 0 -0.12"/>
    <parent link="FL_thigh"/>
    <child link="FL_calf"/>
    <axis xyz="0 1 0"/>
    <dynamics damping="0.0" friction="0.2"/>
    <limit effort="12.0001" lower="-2.55" upper="-0.9" velocity="30.9971"/>
  </joint>
  <link name="FL_calf">
    <visual>
      <origin rpy="0 0 0" xyz="0 0 0"/>
      <geometry>
        <mesh filename="../meshes/FL_calf_link.STL" scale="1 1 1"/>
      </geometry>
      <material name="white"/>
    </visual>
    <collision>
      <origin rpy="0 1.5707963267948966 0" xyz="0 0 -0.08426"/>
      <geometry>
        <box size="0.16852 0.018 0.015"/>
      </geometry>
    </collision>
    <inertial>
      <origin rpy="0 0 0" xyz="5.074e-05 0.0001304 -0.09362007"/>
      <mass value="0.17146643"/>
      <inertia ixx="0.0008322" ixy="9e-08" ixz="3.836e-05" iyy="0.00083464" iyz="-2.18e-06" izz="3.316e-05"/>
    </inertial>
  </link>
  <joint name="FL_foot_fixed" type="fixed" dont_collapse="true">
    <origin rpy="0 0 0" xyz="0 0 -0.16852"/>
    <parent link="FL_calf"/>
    <child link="FL_foot"/>
  </joint>
  <link name="FL_foot">
    <visual>
      <origin rpy="0 0 0" xyz="0 0 0"/>
      <geometry>
        <sphere radius="0.023"/>
        <!-- <mesh filename="package://legged_xxgo_description/meshes/$(arg robot_type)/FL_toe_link.STL" scale="1 1 1"/> -->
      </geometry>
      <material name="white"/>
    </visual>
    <collision>
      <origin rpy="0 0 0" xyz="0 0 0"/>
      <geometry>
        <sphere radius="0.023"/>
      </geometry>
    </collision>
    <inertial>
      <mass value="0.05"/>
      <origin rpy="0 0 0" xyz="3.045e-05 0 -0.00104172"/>
      <inertia ixx="1.0579999999999999e-05" ixy="0.0" ixz="0.0" iyy="1.0579999999999999e-05" iyz="0.0" izz="1.0579999999999999e-05"/>
    </inertial>
    <!-- <inertial>
                <mass value="${0.0}"/>
                <inertia
                        ixx="0.0" ixy="0.0" ixz="0.0"
                        iyy="0.0" iyz="0.0"
                        izz="0.0"/>
            </inertial> -->
    <!-- <inertial>
                <mass value="${foot_mass}"/>
                <origin rpy="0 0 0" xyz="${foot_com_x} ${foot_com_y} ${foot_com_z}"/>
                <inertia
                        ixx="${foot_ixx}" ixy="${foot_ixy}" ixz="${foot_ixz}"
                        iyy="${foot_iyy}" iyz="${foot_iyz}"
                        izz="${foot_izz}"/>
            </inertial> -->
  </link>

  <joint name="RR_hip_joint" type="revolute">
    <origin rpy="0 0 0" xyz="-0.1645 -0.05 0.0"/>
    <parent link="base"/>
    <child link="RR_hip"/>
    <axis xyz="1 0 0"/>
    <dynamics damping="0.0" friction="0.2"/>
    <limit effort="12.0001" lower="-0.45" upper="0.45" velocity="30.9971"/>
  </joint>
  <link name="RR_hip">
    <visual>
      <origin rpy="0 0 3.141592653589793" xyz="0 0 0"/>
      <geometry>
        <mesh filename="../meshes/FL_hip_link.STL" scale="1 1 1"/>
      </geometry>
      <material name="white"/>
    </visual>
    <!-- <collision>
      <origin rpy="1.5707963267948966 0 0" xyz="0 0 0"/>
      <geometry>
        <cylinder length="0.032" radius="0.035"/>
      </geometry>
    </collision> -->
    <inertial>
      <origin rpy="0 0 0" xyz="0.00351874 -0.00206525 -0.00048653"/>
      <mass value="0.3531958"/>
      <inertia ixx="0.00014315" ixy="-1.5e-07" ixz="4e-08" iyy="0.00026346" iyz="1.4e-07" izz="0.00017711"/>
    </inertial>
  </link>
  <joint name="RR_thigh_joint" type="revolute">
    <!-- c -->
    <!-- <origin rpy="0 0 0" xyz="0 ${thigh_offset*mirror} 0"/> -->
    <origin rpy="0 0.0 0" xyz="0 -0.08055 0"/>
    <parent link="RR_hip"/>
    <child link="RR_thigh"/>
    <!-- <axis xyz="0 -1 0"/> -->
    <axis xyz="0 1 0"/>
    <dynamics damping="0.0" friction="0.2"/>
    <limit effort="12.0001" lower="-1" upper="1.79" velocity="30.9971"/>
  </joint>
  <link name="RR_thigh">
    <visual>
      <origin rpy="0 0 0" xyz="0 0 0"/>
      <geometry>
        <mesh filename="../meshes/FR_thigh_link.STL" scale="1 1 1"/>
      </geometry>
      <material name="white"/>
    </visual>
    <collision>
      <origin rpy="0 1.5707963267948966 0" xyz="0 0 -0.06"/>
      <geometry>
        <box size="0.12 0.03 0.03"/>
      </geometry>
    </collision>
    <!-- <collision>
      <origin rpy="1.5707963267948966 0 0" xyz="0 0 0"/>
      <geometry>
        <cylinder length="0.035" radius="0.035"/>
      </geometry>
    </collision> -->
    <inertial>
      <origin rpy="0 0 0" xyz="-0.00371117 0.01697974 -0.01400046"/>
      <mass value="0.71774765"/>
      <inertia ixx="0.00144898" ixy="-5.716e-05" ixz="-0.00011203" iyy="0.00135146" iyz="-0.00019629" izz="0.00071909"/>
    </inertial>
  </link>
  <joint name="RR_calf_joint" type="revolute">
    <!-- cc -->
    <origin rpy="0 0 0" xyz="0 0 -0.12"/>
    <parent link="RR_thigh"/>
    <child link="RR_calf"/>
    <axis xyz="0 1 0"/>
    <dynamics damping="0.0" friction="0.2"/>
    <limit effort="12.0001" lower="-2.55" upper="-0.9" velocity="30.9971"/>
  </joint>
  <link name="RR_calf">
    <visual>
      <origin rpy="0 0 0" xyz="0 0 0"/>
      <geometry>
        <mesh filename="../meshes/FR_calf_link.STL" scale="1 1 1"/>
      </geometry>
      <material name="white"/>
    </visual>
    <collision>
      <origin rpy="0 1.5707963267948966 0" xyz="0 0 -0.08426"/>
      <geometry>
        <box size="0.16852 0.018 0.015"/>
      </geometry>
    </collision>
    <inertial>
      <origin rpy="0 0 0" xyz="5.074e-05 0.0001304 -0.09362007"/>
      <mass value="0.17146643"/>
      <inertia ixx="0.0008322" ixy="9e-08" ixz="3.836e-05" iyy="0.00083464" iyz="-2.18e-06" izz="3.316e-05"/>
    </inertial>
  </link>
  <joint name="RR_foot_fixed" type="fixed" dont_collapse="true">
    <origin rpy="0 0 0" xyz="0 0 -0.16852"/>
    <parent link="RR_calf"/>
    <child link="RR_foot"/>
  </joint>
  <link name="RR_foot">
    <visual>
      <origin rpy="0 0 0" xyz="0 0 0"/>
      <geometry>
        <sphere radius="0.023"/>
        <!-- <mesh filename="package://legged_xxgo_description/meshes/$(arg robot_type)/FL_toe_link.STL" scale="1 1 1"/> -->
      </geometry>
      <material name="white"/>
    </visual>
    <collision>
      <origin rpy="0 0 0" xyz="0 0 0"/>
      <geometry>
        <sphere radius="0.023"/>
      </geometry>
    </collision>
    <inertial>
      <mass value="0.05"/>
      <origin rpy="0 0 0" xyz="3.045e-05 0 -0.00104172"/>
      <inertia ixx="1.0579999999999999e-05" ixy="0.0" ixz="0.0" iyy="1.0579999999999999e-05" iyz="0.0" izz="1.0579999999999999e-05"/>
    </inertial>
    <!-- <inertial>
                <mass value="${0.0}"/>
                <inertia
                        ixx="0.0" ixy="0.0" ixz="0.0"
                        iyy="0.0" iyz="0.0"
                        izz="0.0"/>
            </inertial> -->
    <!-- <inertial>
                <mass value="${foot_mass}"/>
                <origin rpy="0 0 0" xyz="${foot_com_x} ${foot_com_y} ${foot_com_z}"/>
                <inertia
                        ixx="${foot_ixx}" ixy="${foot_ixy}" ixz="${foot_ixz}"
                        iyy="${foot_iyy}" iyz="${foot_iyz}"
                        izz="${foot_izz}"/>
            </inertial> -->
  </link>

  <joint name="RL_hip_joint" type="revolute">
    <origin rpy="0 0 0" xyz="-0.1645 0.05 0.0"/>
    <parent link="base"/>
    <child link="RL_hip"/>
    <axis xyz="1 0 0"/>
    <dynamics damping="0.0" friction="0.2"/>
    <limit effort="12.0001" lower="-0.45" upper="0.45" velocity="30.9971"/>
  </joint>
  <link name="RL_hip">
    <visual>
      <origin rpy="0 0 3.141592653589793" xyz="0 0 0"/>
      <geometry>
        <mesh filename="../meshes/FR_hip_link.STL" scale="1 1 1"/>
      </geometry>
      <material name="white"/>
    </visual>
    <!-- <collision>
      <origin rpy="1.5707963267948966 0 0" xyz="0 0 0"/>
      <geometry>
        <cylinder length="0.032" radius="0.035"/>
      </geometry>
    </collision> -->
    <inertial>
      <origin rpy="0 0 0" xyz="0.00351874 0.00206525 -0.00048653"/>
      <mass value="0.3531958"/>
      <inertia ixx="0.00014315" ixy="1.5e-07" ixz="4e-08" iyy="0.00026346" iyz="-1.4e-07" izz="0.00017711"/>
    </inertial>
  </link>
  <joint name="RL_thigh_joint" type="revolute">
    <!-- c -->
    <!-- <origin rpy="0 0 0" xyz="0 ${thigh_offset*mirror} 0"/> -->
    <origin rpy="0 0.0 0" xyz="0 0.08055 0"/>
    <parent link="RL_hip"/>
    <child link="RL_thigh"/>
    <!-- <axis xyz="0 -1 0"/> -->
    <axis xyz="0 1 0"/>
    <dynamics damping="0.0" friction="0.2"/>
    <limit effort="12.0001" lower="-1" upper="1.79" velocity="30.9971"/>
  </joint>
  <link name="RL_thigh">
    <visual>
      <origin rpy="0 0 0" xyz="0 0 0"/>
      <geometry>
        <mesh filename="../meshes/FL_thigh_link.STL" scale="1 1 1"/>
      </geometry>
      <material name="white"/>
    </visual>
    <collision>
      <origin rpy="0 1.5707963267948966 0" xyz="0 0 -0.06"/>
      <geometry>
        <box size="0.12 0.03 0.03"/>
      </geometry>
    </collision>
    <!-- <collision>
      <origin rpy="1.5707963267948966 0 0" xyz="0 0 0"/>
      <geometry>
        <cylinder length="0.035" radius="0.035"/>
      </geometry>
    </collision> -->
    <inertial>
      <origin rpy="0 0 0" xyz="-0.00371117 -0.01697974 -0.01400046"/>
      <mass value="0.71774765"/>
      <inertia ixx="0.00144898" ixy="5.716e-05" ixz="-0.00011203" iyy="0.00135146" iyz="0.00019629" izz="0.00071909"/>
    </inertial>
  </link>
  <joint name="RL_calf_joint" type="revolute">
    <!-- cc -->
    <origin rpy="0 0 0" xyz="0 0 -0.12"/>
    <parent link="RL_thigh"/>
    <child link="RL_calf"/>
    <axis xyz="0 1 0"/>
    <dynamics damping="0.0" friction="0.2"/>
    <limit effort="12.0001" lower="-2.55" upper="-0.9" velocity="30.9971"/>
  </joint>
  <link name="RL_calf">
    <visual>
      <origin rpy="0 0 0" xyz="0 0 0"/>
      <geometry>
        <mesh filename="../meshes/FL_calf_link.STL" scale="1 1 1"/>
      </geometry>
      <material name="white"/>
    </visual>
    <collision>
      <origin rpy="0 1.5707963267948966 0" xyz="0 0 -0.08426"/>
      <geometry>
        <box size="0.16852 0.018 0.015"/>
      </geometry>
    </collision>
    <inertial>
      <origin rpy="0 0 0" xyz="5.074e-05 0.0001304 -0.09362007"/>
      <mass value="0.17146643"/>
      <inertia ixx="0.0008322" ixy="9e-08" ixz="3.836e-05" iyy="0.00083464" iyz="-2.18e-06" izz="3.316e-05"/>
    </inertial>
  </link>
  <joint name="RL_foot_fixed" type="fixed" dont_collapse="true">
    <origin rpy="0 0 0" xyz="0 0 -0.16852"/>
    <parent link="RL_calf"/>
    <child link="RL_foot"/>
  </joint>
  <link name="RL_foot">
    <visual>
      <origin rpy="0 0 0" xyz="0 0 0"/>
      <geometry>
        <sphere radius="0.023"/>
        <!-- <mesh filename="../meshes/$(arg robot_type)/FL_toe_link.STL" scale="1 1 1"/> -->
      </geometry>
      <material name="white"/>
    </visual>
    <collision>
      <origin rpy="0 0 0" xyz="0 0 0"/>
      <geometry>
        <sphere radius="0.023"/>
      </geometry>
    </collision>
    <inertial>
      <mass value="0.05"/>
      <origin rpy="0 0 0" xyz="3.045e-05 0 -0.00104172"/>
      <inertia ixx="1.0579999999999999e-05" ixy="0.0" ixz="0.0" iyy="1.0579999999999999e-05" iyz="0.0" izz="1.0579999999999999e-05"/>
    </inertial>
    <!-- <inertial>
                <mass value="${0.0}"/>
                <inertia
                        ixx="0.0" ixy="0.0" ixz="0.0"
                        iyy="0.0" iyz="0.0"
                        izz="0.0"/>
            </inertial> -->
    <!-- <inertial>
                <mass value="${foot_mass}"/>
                <origin rpy="0 0 0" xyz="${foot_com_x} ${foot_com_y} ${foot_com_z}"/>
                <inertia
                        ixx="${foot_ixx}" ixy="${foot_ixy}" ixz="${foot_ixz}"
                        iyy="${foot_iyy}" iyz="${foot_iyz}"
                        izz="${foot_izz}"/>
            </inertial> -->
  </link>

  <!-- Robot Footprint -->
  <!-- <joint name="footprint_joint" type="fixed">
        <parent link="base"/>
        <child link="base_footprint"/>
        <origin xyz="0.0 0.0 -0.2" rpy="0 0 0"/>
    </joint>

    <link name="base_footprint">
      <inertial>
      <origin xyz="0 0 0" rpy="${pi/2} 0 ${pi/2}"/>      
      <mass value="0.001"/>
      <inertia ixx="0.0" ixy="0.0" ixz="0.0" iyy="0.0" iyz="0.0" izz="0.0"/>
    </inertial>
    </link>

    <xacro:lidar parent="base" xyz="-0.065 0. 0.1" rpy="0. 0. 0."/> -->
</robot>

