<?xml version="1.0" ?>
<!-- =================================================================================== -->
<!-- |    This document was autogenerated by xacro from /home/gsmp/01_project/arsoft_control/src/legged_control/legged_control/legged_examples/legged_xxgo/legged_xxgo_description/urdf/robot.xacro | -->
<!-- |    EDITING THIS FILE BY HAND IS NOT RECOMMENDED                                 | -->
<!-- =================================================================================== -->
<robot name="robot">
  <material name="black">
    <color rgba="0.0 0.0 0.0 1.0"/>
  </material>
  <material name="blue">
    <color rgba="0.0 0.0 0.8 1.0"/>
  </material>
  <material name="green">
    <color rgba="0.0 0.8 0.0 1.0"/>
  </material>
  <material name="grey">
    <color rgba="0.2 0.2 0.2 1.0"/>
  </material>
  <material name="silver">
    <color rgba="0.9137254901960784 0.9137254901960784 0.8470588235294118 1.0"/>
  </material>
  <material name="orange">
    <color rgba="1.0 0.4235294117647059 0.0392156862745098 1.0"/>
  </material>
  <material name="brown">
    <color rgba="0.8705882352941177 0.8117647058823529 0.7647058823529411 1.0"/>
  </material>
  <material name="red">
    <color rgba="0.8 0.0 0.0 1.0"/>
  </material>
  <material name="white">
    <color rgba="1.0 1.0 1.0 1.0"/>
  </material>
  <!-- ros_control plugin -->
  <gazebo>
    <plugin filename="liblegged_hw_sim.so" name="gazebo_ros_control">
      <robotNamespace>/</robotNamespace>
      <robotParam>legged_robot_description</robotParam>
      <robotSimType>legged_gazebo/LeggedHWSim</robotSimType>
    </plugin>
  </gazebo>
  <gazebo>
    <plugin filename="libgazebo_ros_p3d.so" name="p3d_base_controller">
      <alwaysOn>true</alwaysOn>
      <updateRate>1000.0</updateRate>
      <bodyName>base</bodyName>
      <topicName>ground_truth/state</topicName>
      <gaussianNoise>0</gaussianNoise>
      <frameName>world</frameName>
      <xyzOffsets>0 0 0</xyzOffsets>
      <rpyOffsets>0 0 0</rpyOffsets>
    </plugin>
  </gazebo>
  <gazebo reference="base_link">
    <maxVel>100.</maxVel>
    <kp>10000.</kp>
    <kd>0.</kd>
  </gazebo>
  <gazebo reference="stick_link">
    <mu1>0.2</mu1>
    <mu2>0.2</mu2>
    <material>Gazebo/White</material>
  </gazebo>
  <!-- LF leg -->
  <gazebo reference="LF_hip">
    <mu1>0.2</mu1>
    <mu2>0.2</mu2>
    <material>Gazebo/DarkGrey</material>
  </gazebo>
  <gazebo reference="LF_thigh">
    <mu1>0.2</mu1>
    <mu2>0.2</mu2>
    <self_collide>1</self_collide>
    <material>Gazebo/DarkGrey</material>
    <kp value="1000000.0"/>
    <kd value="1.0"/>
  </gazebo>
  <gazebo reference="LF_calf">
    <mu1>0.2</mu1>
    <mu2>0.2</mu2>
    <self_collide>1</self_collide>
  </gazebo>
  <gazebo reference="LF_FOOT">
    <mu1>100</mu1>
    <mu2>100</mu2>
    <self_collide>1</self_collide>
    <material>Gazebo/DarkGrey</material>
    <kp value="1000000.0"/>
    <kd value="100.0"/>
  </gazebo>
  <!-- RF leg -->
  <gazebo reference="RF_hip">
    <mu1>0.2</mu1>
    <mu2>0.2</mu2>
    <material>Gazebo/DarkGrey</material>
  </gazebo>
  <gazebo reference="RF_thigh">
    <mu1>0.2</mu1>
    <mu2>0.2</mu2>
    <self_collide>1</self_collide>
    <material>Gazebo/DarkGrey</material>
    <kp value="1000000.0"/>
    <kd value="1.0"/>
  </gazebo>
  <gazebo reference="RF_calf">
    <mu1>0.2</mu1>
    <mu2>0.2</mu2>
    <self_collide>1</self_collide>
  </gazebo>
  <gazebo reference="RF_FOOT">
    <mu1>100</mu1>
    <mu2>100</mu2>
    <self_collide>1</self_collide>
    <material>Gazebo/DarkGrey</material>
    <kp value="1000000.0"/>
    <kd value="1.0"/>
  </gazebo>
  <!-- LH leg -->
  <gazebo reference="LH_hip">
    <mu1>0.2</mu1>
    <mu2>0.2</mu2>
    <material>Gazebo/DarkGrey</material>
  </gazebo>
  <gazebo reference="LH_thigh">
    <mu1>0.2</mu1>
    <mu2>0.2</mu2>
    <self_collide>1</self_collide>
    <material>Gazebo/DarkGrey</material>
    <kp value="1000000.0"/>
    <kd value="1.0"/>
  </gazebo>
  <gazebo reference="LH_calf">
    <mu1>0.2</mu1>
    <mu2>0.2</mu2>
    <self_collide>1</self_collide>
  </gazebo>
  <gazebo reference="LH_FOOT">
    <mu1>100</mu1>
    <mu2>100</mu2>
    <self_collide>1</self_collide>
    <material>Gazebo/DarkGrey</material>
    <kp value="1000000.0"/>
    <kd value="1.0"/>
  </gazebo>
  <!-- RH leg -->
  <gazebo reference="RH_hip">
    <mu1>0.2</mu1>
    <mu2>0.2</mu2>
    <material>Gazebo/DarkGrey</material>
  </gazebo>
  <gazebo reference="RH_thigh">
    <mu1>0.2</mu1>
    <mu2>0.2</mu2>
    <self_collide>1</self_collide>
    <material>Gazebo/DarkGrey</material>
    <kp value="1000000.0"/>
    <kd value="1.0"/>
  </gazebo>
  <gazebo reference="RH_calf">
    <mu1>0.2</mu1>
    <mu2>0.2</mu2>
    <self_collide>1</self_collide>
  </gazebo>
  <gazebo reference="RH_FOOT">
    <mu1>100</mu1>
    <mu2>100</mu2>
    <self_collide>1</self_collide>
    <material>Gazebo/DarkGrey</material>
    <kp value="1000000.0"/>
    <kd value="1.0"/>
  </gazebo>
  <!-- <xacro:property name="foot_com_x" value="-0.0042403"/>
    <xacro:property name="foot_com_y" value="-8.0676E-11"/>
    <xacro:property name="foot_com_z" value="-0.0056271"/>

    <xacro:property name="foot_ixx" value="1.2054E-06"/>
    <xacro:property name="foot_ixy" value="-5.2111E-13"/>
    <xacro:property name="foot_ixz" value="3.5566E-07"/>
    <xacro:property name="foot_iyy" value="1.5621E-06"/>
    <xacro:property name="foot_iyz" value="3.996E-13"/>
    <xacro:property name="foot_izz" value="1.4093E-06"/> -->
  <!-- <link name="world" />

    <joint name ="weld" type="fixed">
        <parent link="world"/>
        <child link="base"/>
        <origin xyz="0 0 1"/>
    </joint> -->
  <link name="base">
    <visual>
      <origin rpy="0 0 0" xyz="0 0 0"/>
      <geometry>
        <mesh filename="package://legged_xxgo_description/meshes/xxgo/trunk.STL" scale="1 1 1"/>
      </geometry>
      <material name="white"/>
    </visual>
    <collision>
      <origin rpy="0 0 0" xyz="0 0 0"/>
      <geometry>
        <box size="0.238 0.18 0.14"/>
      </geometry>
    </collision>
    <inertial>
      <origin rpy="0 0 0" xyz="-0.02248608 -0.00011879 -0.00679147"/>
      <mass value="4.1430459"/>
      <inertia ixx="0.01454145" ixy="0.00017282" ixz="-0.00014576" iyy="0.02842016" iyz="4.241e-05" izz="0.03523081"/>
    </inertial>
  </link>
  <!-- Imu is fixed to the base link -->
  <joint name="base_imu_joint" type="fixed">
    <origin rpy="0. 0. 0." xyz="0. 0. 0."/>
    <parent link="base"/>
    <child link="base_imu"/>
  </joint>
  <!-- Imu link -->
  <link name="base_imu">
    <inertial>
      <mass value="0.01"/>
      <origin rpy="0 0 0" xyz="0 0 0"/>
      <inertia ixx="0.000001" ixy="0" ixz="0" iyy="0.000001" iyz="0" izz="0.000001"/>
    </inertial>
    <visual>
      <origin rpy="0 0 0" xyz="0 0 0"/>
      <geometry>
        <box size="0.015 0.015 0.004"/>
      </geometry>
    </visual>
    <material name="orange">
      <color rgba="255 108 10 255"/>
    </material>
  </link>
  <gazebo reference="base_imu">
    <material>Gazebo/Orange</material>
  </gazebo>
  <gazebo reference="base_imu_joint">
    <disableFixedJointLumping>true</disableFixedJointLumping>
  </gazebo>
  <joint name="RF_HAA" type="revolute">
    <origin rpy="0 0 0" xyz="0.1645 -0.05 0.0"/>
    <parent link="base"/>
    <child link="RF_hip"/>
    <axis xyz="1 0 0"/>
    <dynamics damping="0.0" friction="0.2"/>
    <limit effort="12.0001" lower="-0.33" upper="0.33" velocity="30.9971"/>
  </joint>
  <link name="RF_hip">
    <visual>
      <origin rpy="0 0 0" xyz="0 0 0"/>
      <!-- <origin rpy="${pi} 0 0" xyz="0 0 0"/> -->
      <geometry>
        <mesh filename="package://legged_xxgo_description/meshes/xxgo/FR_hip_link.STL" scale="1 1 1"/>
      </geometry>
      <material name="white"/>
    </visual>
    <collision>
      <origin rpy="1.5707963267948966 0 0" xyz="0 0 0"/>
      <geometry>
        <cylinder length="0.032" radius="0.035"/>
      </geometry>
    </collision>
    <inertial>
      <origin rpy="0 0 0" xyz="-0.00351874 -0.00206525 -0.00048653"/>
      <mass value="0.3531958"/>
      <inertia ixx="0.00014315" ixy="1.5e-07" ixz="-4e-08" iyy="0.00026346" iyz="1.4e-07" izz="0.00017711"/>
    </inertial>
  </link>
  <joint name="RF_HFE" type="revolute">
    <!-- c -->
    <!-- <origin rpy="0 0 0" xyz="0 ${thigh_offset*mirror} 0"/> -->
    <origin rpy="0 0.0 0" xyz="0 -0.08055 0"/>
    <parent link="RF_hip"/>
    <child link="RF_thigh"/>
    <!-- <axis xyz="0 -1 0"/> -->
    <axis xyz="0 1 0"/>
    <dynamics damping="0.0" friction="0.2"/>
    <limit effort="12.0001" lower="-1" upper="1.79" velocity="30.9971"/>
  </joint>
  <link name="RF_thigh">
    <visual>
      <origin rpy="0 0 0" xyz="0 0 0"/>
      <geometry>
        <mesh filename="package://legged_xxgo_description/meshes/xxgo/FR_thigh_link.STL" scale="1 1 1"/>
      </geometry>
      <material name="white"/>
    </visual>
    <collision>
      <origin rpy="0 1.5707963267948966 0" xyz="0 0 -0.06"/>
      <geometry>
        <box size="0.12 0.03 0.03"/>
      </geometry>
    </collision>
    <collision>
      <origin rpy="1.5707963267948966 0 0" xyz="0 0 0"/>
      <geometry>
        <cylinder length="0.035" radius="0.035"/>
      </geometry>
    </collision>
    <inertial>
      <origin rpy="0 0 0" xyz="-0.00371117 0.01697974 -0.01400046"/>
      <mass value="0.71774765"/>
      <inertia ixx="0.00144898" ixy="-5.716e-05" ixz="-0.00011203" iyy="0.00135146" iyz="-0.00019629" izz="0.00071909"/>
    </inertial>
  </link>
  <joint name="RF_KFE" type="revolute">
    <!-- cc -->
    <origin rpy="0 0 0" xyz="0 0 -0.12"/>
    <parent link="RF_thigh"/>
    <child link="RF_calf"/>
    <axis xyz="0 1 0"/>
    <dynamics damping="0.0" friction="0.2"/>
    <limit effort="12.0001" lower="-2.65" upper="-0.9" velocity="30.9971"/>
  </joint>
  <link name="RF_calf">
    <visual>
      <origin rpy="0 0 0" xyz="0 0 0"/>
      <geometry>
        <mesh filename="package://legged_xxgo_description/meshes/xxgo/FR_calf_link.STL" scale="1 1 1"/>
      </geometry>
      <material name="white"/>
    </visual>
    <collision>
      <origin rpy="0 1.5707963267948966 0" xyz="0 0 -0.08426"/>
      <geometry>
        <box size="0.16852 0.018 0.015"/>
      </geometry>
    </collision>
    <inertial>
      <origin rpy="0 0 0" xyz="5.074e-05 0.0001304 -0.09362007"/>
      <mass value="0.17146643"/>
      <inertia ixx="0.0008322" ixy="9e-08" ixz="3.836e-05" iyy="0.00083464" iyz="-2.18e-06" izz="3.316e-05"/>
    </inertial>
  </link>
  <joint name="RF_foot_fixed" type="fixed">
    <origin rpy="0 0 0" xyz="0 0 -0.16852"/>
    <parent link="RF_calf"/>
    <child link="RF_FOOT"/>
  </joint>
  <link name="RF_FOOT">
    <visual>
      <origin rpy="0 0 0" xyz="0 0 0"/>
      <geometry>
        <sphere radius="0.023"/>
        <!-- <mesh filename="package://legged_xxgo_description/meshes/$(arg robot_type)/FL_toe_link.STL" scale="1 1 1"/> -->
      </geometry>
      <material name="white"/>
    </visual>
    <collision>
      <origin rpy="0 0 0" xyz="0 0 0"/>
      <geometry>
        <sphere radius="0.023"/>
      </geometry>
    </collision>
    <inertial>
      <mass value="0.05"/>
      <inertia ixx="1.0579999999999999e-05" ixy="0.0" ixz="0.0" iyy="1.0579999999999999e-05" iyz="0.0" izz="1.0579999999999999e-05"/>
    </inertial>
    <!-- <inertial>
                <mass value="${0.0}"/>
                <inertia
                        ixx="0.0" ixy="0.0" ixz="0.0"
                        iyy="0.0" iyz="0.0"
                        izz="0.0"/>
            </inertial> -->
    <!-- <inertial>
                <mass value="${foot_mass}"/>
                <origin rpy="0 0 0" xyz="${foot_com_x} ${foot_com_y} ${foot_com_z}"/>
                <inertia
                        ixx="${foot_ixx}" ixy="${foot_ixy}" ixz="${foot_ixz}"
                        iyy="${foot_iyy}" iyz="${foot_iyz}"
                        izz="${foot_izz}"/>
            </inertial> -->
  </link>
  <gazebo reference="RF_foot_fixed">
    <disableFixedJointLumping>true</disableFixedJointLumping>
  </gazebo>
  <transmission name="RF_HAA_tran">
    <type>transmission_interface/SimpleTransmission</type>
    <joint name="RF_HAA">
      <hardwareInterface>hardware_interface/EffortJointInterface</hardwareInterface>
    </joint>
    <actuator name="RF_HAA_motor">
      <hardwareInterface>hardware_interface/EffortJointInterface</hardwareInterface>
      <mechanicalReduction>1</mechanicalReduction>
    </actuator>
  </transmission>
  <transmission name="RF_HFE_tran">
    <type>transmission_interface/SimpleTransmission</type>
    <joint name="RF_HFE">
      <hardwareInterface>hardware_interface/EffortJointInterface</hardwareInterface>
    </joint>
    <actuator name="RF_HFE_motor">
      <hardwareInterface>hardware_interface/EffortJointInterface</hardwareInterface>
      <mechanicalReduction>1</mechanicalReduction>
    </actuator>
  </transmission>
  <transmission name="RF_KFE_tran">
    <type>transmission_interface/SimpleTransmission</type>
    <joint name="RF_KFE">
      <hardwareInterface>hardware_interface/EffortJointInterface</hardwareInterface>
    </joint>
    <actuator name="RF_KFE_motor">
      <hardwareInterface>hardware_interface/EffortJointInterface</hardwareInterface>
      <mechanicalReduction>1</mechanicalReduction>
    </actuator>
  </transmission>
  <joint name="LF_HAA" type="revolute">
    <origin rpy="0 0 0" xyz="0.1645 0.05 0.0"/>
    <parent link="base"/>
    <child link="LF_hip"/>
    <axis xyz="1 0 0"/>
    <dynamics damping="0.0" friction="0.2"/>
    <limit effort="12.0001" lower="-0.33" upper="0.33" velocity="30.9971"/>
  </joint>
  <link name="LF_hip">
    <visual>
      <origin rpy="0 0 0" xyz="0 0 0"/>
      <geometry>
        <mesh filename="package://legged_xxgo_description/meshes/xxgo/FL_hip_link.STL" scale="1 1 1"/>
      </geometry>
      <material name="white"/>
    </visual>
    <collision>
      <origin rpy="1.5707963267948966 0 0" xyz="0 0 0"/>
      <geometry>
        <cylinder length="0.032" radius="0.035"/>
      </geometry>
    </collision>
    <inertial>
      <origin rpy="0 0 0" xyz="-0.00351874 0.00206525 -0.00048653"/>
      <mass value="0.3531958"/>
      <inertia ixx="0.00014315" ixy="-1.5e-07" ixz="-4e-08" iyy="0.00026346" iyz="-1.4e-07" izz="0.00017711"/>
    </inertial>
  </link>
  <joint name="LF_HFE" type="revolute">
    <!-- c -->
    <!-- <origin rpy="0 0 0" xyz="0 ${thigh_offset*mirror} 0"/> -->
    <origin rpy="0 0.0 0" xyz="0 0.08055 0"/>
    <parent link="LF_hip"/>
    <child link="LF_thigh"/>
    <!-- <axis xyz="0 -1 0"/> -->
    <axis xyz="0 1 0"/>
    <dynamics damping="0.0" friction="0.2"/>
    <limit effort="12.0001" lower="-1" upper="1.79" velocity="30.9971"/>
  </joint>
  <link name="LF_thigh">
    <visual>
      <origin rpy="0 0 0" xyz="0 0 0"/>
      <geometry>
        <mesh filename="package://legged_xxgo_description/meshes/xxgo/FL_thigh_link.STL" scale="1 1 1"/>
      </geometry>
      <material name="white"/>
    </visual>
    <collision>
      <origin rpy="0 1.5707963267948966 0" xyz="0 0 -0.06"/>
      <geometry>
        <box size="0.12 0.03 0.03"/>
      </geometry>
    </collision>
    <collision>
      <origin rpy="1.5707963267948966 0 0" xyz="0 0 0"/>
      <geometry>
        <cylinder length="0.035" radius="0.035"/>
      </geometry>
    </collision>
    <inertial>
      <origin rpy="0 0 0" xyz="-0.00371117 -0.01697974 -0.01400046"/>
      <mass value="0.71774765"/>
      <inertia ixx="0.00144898" ixy="5.716e-05" ixz="-0.00011203" iyy="0.00135146" iyz="0.00019629" izz="0.00071909"/>
    </inertial>
  </link>
  <joint name="LF_KFE" type="revolute">
    <!-- cc -->
    <origin rpy="0 0 0" xyz="0 0 -0.12"/>
    <parent link="LF_thigh"/>
    <child link="LF_calf"/>
    <axis xyz="0 1 0"/>
    <dynamics damping="0.0" friction="0.2"/>
    <limit effort="12.0001" lower="-2.65" upper="-0.9" velocity="30.9971"/>
  </joint>
  <link name="LF_calf">
    <visual>
      <origin rpy="0 0 0" xyz="0 0 0"/>
      <geometry>
        <mesh filename="package://legged_xxgo_description/meshes/xxgo/FL_calf_link.STL" scale="1 1 1"/>
      </geometry>
      <material name="white"/>
    </visual>
    <collision>
      <origin rpy="0 1.5707963267948966 0" xyz="0 0 -0.08426"/>
      <geometry>
        <box size="0.16852 0.018 0.015"/>
      </geometry>
    </collision>
    <inertial>
      <origin rpy="0 0 0" xyz="5.074e-05 0.0001304 -0.09362007"/>
      <mass value="0.17146643"/>
      <inertia ixx="0.0008322" ixy="9e-08" ixz="3.836e-05" iyy="0.00083464" iyz="-2.18e-06" izz="3.316e-05"/>
    </inertial>
  </link>
  <joint name="LF_foot_fixed" type="fixed">
    <origin rpy="0 0 0" xyz="0 0 -0.16852"/>
    <parent link="LF_calf"/>
    <child link="LF_FOOT"/>
  </joint>
  <link name="LF_FOOT">
    <visual>
      <origin rpy="0 0 0" xyz="0 0 0"/>
      <geometry>
        <sphere radius="0.023"/>
        <!-- <mesh filename="package://legged_xxgo_description/meshes/$(arg robot_type)/FL_toe_link.STL" scale="1 1 1"/> -->
      </geometry>
      <material name="white"/>
    </visual>
    <collision>
      <origin rpy="0 0 0" xyz="0 0 0"/>
      <geometry>
        <sphere radius="0.023"/>
      </geometry>
    </collision>
    <inertial>
      <mass value="0.05"/>
      <inertia ixx="1.0579999999999999e-05" ixy="0.0" ixz="0.0" iyy="1.0579999999999999e-05" iyz="0.0" izz="1.0579999999999999e-05"/>
    </inertial>
    <!-- <inertial>
                <mass value="${0.0}"/>
                <inertia
                        ixx="0.0" ixy="0.0" ixz="0.0"
                        iyy="0.0" iyz="0.0"
                        izz="0.0"/>
            </inertial> -->
    <!-- <inertial>
                <mass value="${foot_mass}"/>
                <origin rpy="0 0 0" xyz="${foot_com_x} ${foot_com_y} ${foot_com_z}"/>
                <inertia
                        ixx="${foot_ixx}" ixy="${foot_ixy}" ixz="${foot_ixz}"
                        iyy="${foot_iyy}" iyz="${foot_iyz}"
                        izz="${foot_izz}"/>
            </inertial> -->
  </link>
  <gazebo reference="LF_foot_fixed">
    <disableFixedJointLumping>true</disableFixedJointLumping>
  </gazebo>
  <transmission name="LF_HAA_tran">
    <type>transmission_interface/SimpleTransmission</type>
    <joint name="LF_HAA">
      <hardwareInterface>hardware_interface/EffortJointInterface</hardwareInterface>
    </joint>
    <actuator name="LF_HAA_motor">
      <hardwareInterface>hardware_interface/EffortJointInterface</hardwareInterface>
      <mechanicalReduction>1</mechanicalReduction>
    </actuator>
  </transmission>
  <transmission name="LF_HFE_tran">
    <type>transmission_interface/SimpleTransmission</type>
    <joint name="LF_HFE">
      <hardwareInterface>hardware_interface/EffortJointInterface</hardwareInterface>
    </joint>
    <actuator name="LF_HFE_motor">
      <hardwareInterface>hardware_interface/EffortJointInterface</hardwareInterface>
      <mechanicalReduction>1</mechanicalReduction>
    </actuator>
  </transmission>
  <transmission name="LF_KFE_tran">
    <type>transmission_interface/SimpleTransmission</type>
    <joint name="LF_KFE">
      <hardwareInterface>hardware_interface/EffortJointInterface</hardwareInterface>
    </joint>
    <actuator name="LF_KFE_motor">
      <hardwareInterface>hardware_interface/EffortJointInterface</hardwareInterface>
      <mechanicalReduction>1</mechanicalReduction>
    </actuator>
  </transmission>
  <joint name="RH_HAA" type="revolute">
    <origin rpy="0 0 0" xyz="-0.1645 -0.05 0.0"/>
    <parent link="base"/>
    <child link="RH_hip"/>
    <axis xyz="1 0 0"/>
    <dynamics damping="0.0" friction="0.2"/>
    <limit effort="12.0001" lower="-0.33" upper="0.33" velocity="30.9971"/>
  </joint>
  <link name="RH_hip">
    <visual>
      <origin rpy="0 0 3.141592653589793" xyz="0 0 0"/>
      <geometry>
        <mesh filename="package://legged_xxgo_description/meshes/xxgo/FL_hip_link.STL" scale="1 1 1"/>
      </geometry>
      <material name="white"/>
    </visual>
    <collision>
      <origin rpy="1.5707963267948966 0 0" xyz="0 0 0"/>
      <geometry>
        <cylinder length="0.032" radius="0.035"/>
      </geometry>
    </collision>
    <inertial>
      <origin rpy="0 0 0" xyz="0.00351874 -0.00206525 -0.00048653"/>
      <mass value="0.3531958"/>
      <inertia ixx="0.00014315" ixy="-1.5e-07" ixz="4e-08" iyy="0.00026346" iyz="1.4e-07" izz="0.00017711"/>
    </inertial>
  </link>
  <joint name="RH_HFE" type="revolute">
    <!-- c -->
    <!-- <origin rpy="0 0 0" xyz="0 ${thigh_offset*mirror} 0"/> -->
    <origin rpy="0 0.0 0" xyz="0 -0.08055 0"/>
    <parent link="RH_hip"/>
    <child link="RH_thigh"/>
    <!-- <axis xyz="0 -1 0"/> -->
    <axis xyz="0 1 0"/>
    <dynamics damping="0.0" friction="0.2"/>
    <limit effort="12.0001" lower="-1" upper="1.79" velocity="30.9971"/>
  </joint>
  <link name="RH_thigh">
    <visual>
      <origin rpy="0 0 0" xyz="0 0 0"/>
      <geometry>
        <mesh filename="package://legged_xxgo_description/meshes/xxgo/FR_thigh_link.STL" scale="1 1 1"/>
      </geometry>
      <material name="white"/>
    </visual>
    <collision>
      <origin rpy="0 1.5707963267948966 0" xyz="0 0 -0.06"/>
      <geometry>
        <box size="0.12 0.03 0.03"/>
      </geometry>
    </collision>
    <collision>
      <origin rpy="1.5707963267948966 0 0" xyz="0 0 0"/>
      <geometry>
        <cylinder length="0.035" radius="0.035"/>
      </geometry>
    </collision>
    <inertial>
      <origin rpy="0 0 0" xyz="-0.00371117 0.01697974 -0.01400046"/>
      <mass value="0.71774765"/>
      <inertia ixx="0.00144898" ixy="-5.716e-05" ixz="-0.00011203" iyy="0.00135146" iyz="-0.00019629" izz="0.00071909"/>
    </inertial>
  </link>
  <joint name="RH_KFE" type="revolute">
    <!-- cc -->
    <origin rpy="0 0 0" xyz="0 0 -0.12"/>
    <parent link="RH_thigh"/>
    <child link="RH_calf"/>
    <axis xyz="0 1 0"/>
    <dynamics damping="0.0" friction="0.2"/>
    <limit effort="12.0001" lower="-2.65" upper="-0.9" velocity="30.9971"/>
  </joint>
  <link name="RH_calf">
    <visual>
      <origin rpy="0 0 0" xyz="0 0 0"/>
      <geometry>
        <mesh filename="package://legged_xxgo_description/meshes/xxgo/FR_calf_link.STL" scale="1 1 1"/>
      </geometry>
      <material name="white"/>
    </visual>
    <collision>
      <origin rpy="0 1.5707963267948966 0" xyz="0 0 -0.08426"/>
      <geometry>
        <box size="0.16852 0.018 0.015"/>
      </geometry>
    </collision>
    <inertial>
      <origin rpy="0 0 0" xyz="5.074e-05 0.0001304 -0.09362007"/>
      <mass value="0.17146643"/>
      <inertia ixx="0.0008322" ixy="9e-08" ixz="3.836e-05" iyy="0.00083464" iyz="-2.18e-06" izz="3.316e-05"/>
    </inertial>
  </link>
  <joint name="RH_foot_fixed" type="fixed">
    <origin rpy="0 0 0" xyz="0 0 -0.16852"/>
    <parent link="RH_calf"/>
    <child link="RH_FOOT"/>
  </joint>
  <link name="RH_FOOT">
    <visual>
      <origin rpy="0 0 0" xyz="0 0 0"/>
      <geometry>
        <sphere radius="0.023"/>
        <!-- <mesh filename="package://legged_xxgo_description/meshes/$(arg robot_type)/FL_toe_link.STL" scale="1 1 1"/> -->
      </geometry>
      <material name="white"/>
    </visual>
    <collision>
      <origin rpy="0 0 0" xyz="0 0 0"/>
      <geometry>
        <sphere radius="0.023"/>
      </geometry>
    </collision>
    <inertial>
      <mass value="0.05"/>
      <inertia ixx="1.0579999999999999e-05" ixy="0.0" ixz="0.0" iyy="1.0579999999999999e-05" iyz="0.0" izz="1.0579999999999999e-05"/>
    </inertial>
    <!-- <inertial>
                <mass value="${0.0}"/>
                <inertia
                        ixx="0.0" ixy="0.0" ixz="0.0"
                        iyy="0.0" iyz="0.0"
                        izz="0.0"/>
            </inertial> -->
    <!-- <inertial>
                <mass value="${foot_mass}"/>
                <origin rpy="0 0 0" xyz="${foot_com_x} ${foot_com_y} ${foot_com_z}"/>
                <inertia
                        ixx="${foot_ixx}" ixy="${foot_ixy}" ixz="${foot_ixz}"
                        iyy="${foot_iyy}" iyz="${foot_iyz}"
                        izz="${foot_izz}"/>
            </inertial> -->
  </link>
  <gazebo reference="RH_foot_fixed">
    <disableFixedJointLumping>true</disableFixedJointLumping>
  </gazebo>
  <transmission name="RH_HAA_tran">
    <type>transmission_interface/SimpleTransmission</type>
    <joint name="RH_HAA">
      <hardwareInterface>hardware_interface/EffortJointInterface</hardwareInterface>
    </joint>
    <actuator name="RH_HAA_motor">
      <hardwareInterface>hardware_interface/EffortJointInterface</hardwareInterface>
      <mechanicalReduction>1</mechanicalReduction>
    </actuator>
  </transmission>
  <transmission name="RH_HFE_tran">
    <type>transmission_interface/SimpleTransmission</type>
    <joint name="RH_HFE">
      <hardwareInterface>hardware_interface/EffortJointInterface</hardwareInterface>
    </joint>
    <actuator name="RH_HFE_motor">
      <hardwareInterface>hardware_interface/EffortJointInterface</hardwareInterface>
      <mechanicalReduction>1</mechanicalReduction>
    </actuator>
  </transmission>
  <transmission name="RH_KFE_tran">
    <type>transmission_interface/SimpleTransmission</type>
    <joint name="RH_KFE">
      <hardwareInterface>hardware_interface/EffortJointInterface</hardwareInterface>
    </joint>
    <actuator name="RH_KFE_motor">
      <hardwareInterface>hardware_interface/EffortJointInterface</hardwareInterface>
      <mechanicalReduction>1</mechanicalReduction>
    </actuator>
  </transmission>
  <joint name="LH_HAA" type="revolute">
    <origin rpy="0 0 0" xyz="-0.1645 0.05 0.0"/>
    <parent link="base"/>
    <child link="LH_hip"/>
    <axis xyz="1 0 0"/>
    <dynamics damping="0.0" friction="0.2"/>
    <limit effort="12.0001" lower="-0.33" upper="0.33" velocity="30.9971"/>
  </joint>
  <link name="LH_hip">
    <visual>
      <origin rpy="0 0 3.141592653589793" xyz="0 0 0"/>
      <geometry>
        <mesh filename="package://legged_xxgo_description/meshes/xxgo/FR_hip_link.STL" scale="1 1 1"/>
      </geometry>
      <material name="white"/>
    </visual>
    <collision>
      <origin rpy="1.5707963267948966 0 0" xyz="0 0 0"/>
      <geometry>
        <cylinder length="0.032" radius="0.035"/>
      </geometry>
    </collision>
    <inertial>
      <origin rpy="0 0 0" xyz="0.00351874 0.00206525 -0.00048653"/>
      <mass value="0.3531958"/>
      <inertia ixx="0.00014315" ixy="1.5e-07" ixz="4e-08" iyy="0.00026346" iyz="-1.4e-07" izz="0.00017711"/>
    </inertial>
  </link>
  <joint name="LH_HFE" type="revolute">
    <!-- c -->
    <!-- <origin rpy="0 0 0" xyz="0 ${thigh_offset*mirror} 0"/> -->
    <origin rpy="0 0.0 0" xyz="0 0.08055 0"/>
    <parent link="LH_hip"/>
    <child link="LH_thigh"/>
    <!-- <axis xyz="0 -1 0"/> -->
    <axis xyz="0 1 0"/>
    <dynamics damping="0.0" friction="0.2"/>
    <limit effort="12.0001" lower="-1" upper="1.79" velocity="30.9971"/>
  </joint>
  <link name="LH_thigh">
    <visual>
      <origin rpy="0 0 0" xyz="0 0 0"/>
      <geometry>
        <mesh filename="package://legged_xxgo_description/meshes/xxgo/FL_thigh_link.STL" scale="1 1 1"/>
      </geometry>
      <material name="white"/>
    </visual>
    <collision>
      <origin rpy="0 1.5707963267948966 0" xyz="0 0 -0.06"/>
      <geometry>
        <box size="0.12 0.03 0.03"/>
      </geometry>
    </collision>
    <collision>
      <origin rpy="1.5707963267948966 0 0" xyz="0 0 0"/>
      <geometry>
        <cylinder length="0.035" radius="0.035"/>
      </geometry>
    </collision>
    <inertial>
      <origin rpy="0 0 0" xyz="-0.00371117 -0.01697974 -0.01400046"/>
      <mass value="0.71774765"/>
      <inertia ixx="0.00144898" ixy="5.716e-05" ixz="-0.00011203" iyy="0.00135146" iyz="0.00019629" izz="0.00071909"/>
    </inertial>
  </link>
  <joint name="LH_KFE" type="revolute">
    <!-- cc -->
    <origin rpy="0 0 0" xyz="0 0 -0.12"/>
    <parent link="LH_thigh"/>
    <child link="LH_calf"/>
    <axis xyz="0 1 0"/>
    <dynamics damping="0.0" friction="0.2"/>
    <limit effort="12.0001" lower="-2.65" upper="-0.9" velocity="30.9971"/>
  </joint>
  <link name="LH_calf">
    <visual>
      <origin rpy="0 0 0" xyz="0 0 0"/>
      <geometry>
        <mesh filename="package://legged_xxgo_description/meshes/xxgo/FL_calf_link.STL" scale="1 1 1"/>
      </geometry>
      <material name="white"/>
    </visual>
    <collision>
      <origin rpy="0 1.5707963267948966 0" xyz="0 0 -0.08426"/>
      <geometry>
        <box size="0.16852 0.018 0.015"/>
      </geometry>
    </collision>
    <inertial>
      <origin rpy="0 0 0" xyz="5.074e-05 0.0001304 -0.09362007"/>
      <mass value="0.17146643"/>
      <inertia ixx="0.0008322" ixy="9e-08" ixz="3.836e-05" iyy="0.00083464" iyz="-2.18e-06" izz="3.316e-05"/>
    </inertial>
  </link>
  <joint name="LH_foot_fixed" type="fixed">
    <origin rpy="0 0 0" xyz="0 0 -0.16852"/>
    <parent link="LH_calf"/>
    <child link="LH_FOOT"/>
  </joint>
  <link name="LH_FOOT">
    <visual>
      <origin rpy="0 0 0" xyz="0 0 0"/>
      <geometry>
        <sphere radius="0.023"/>
        <!-- <mesh filename="package://legged_xxgo_description/meshes/$(arg robot_type)/FL_toe_link.STL" scale="1 1 1"/> -->
      </geometry>
      <material name="white"/>
    </visual>
    <collision>
      <origin rpy="0 0 0" xyz="0 0 0"/>
      <geometry>
        <sphere radius="0.023"/>
      </geometry>
    </collision>
    <inertial>
      <mass value="0.05"/>
      <inertia ixx="1.0579999999999999e-05" ixy="0.0" ixz="0.0" iyy="1.0579999999999999e-05" iyz="0.0" izz="1.0579999999999999e-05"/>
    </inertial>
    <!-- <inertial>
                <mass value="${0.0}"/>
                <inertia
                        ixx="0.0" ixy="0.0" ixz="0.0"
                        iyy="0.0" iyz="0.0"
                        izz="0.0"/>
            </inertial> -->
    <!-- <inertial>
                <mass value="${foot_mass}"/>
                <origin rpy="0 0 0" xyz="${foot_com_x} ${foot_com_y} ${foot_com_z}"/>
                <inertia
                        ixx="${foot_ixx}" ixy="${foot_ixy}" ixz="${foot_ixz}"
                        iyy="${foot_iyy}" iyz="${foot_iyz}"
                        izz="${foot_izz}"/>
            </inertial> -->
  </link>
  <gazebo reference="LH_foot_fixed">
    <disableFixedJointLumping>true</disableFixedJointLumping>
  </gazebo>
  <transmission name="LH_HAA_tran">
    <type>transmission_interface/SimpleTransmission</type>
    <joint name="LH_HAA">
      <hardwareInterface>hardware_interface/EffortJointInterface</hardwareInterface>
    </joint>
    <actuator name="LH_HAA_motor">
      <hardwareInterface>hardware_interface/EffortJointInterface</hardwareInterface>
      <mechanicalReduction>1</mechanicalReduction>
    </actuator>
  </transmission>
  <transmission name="LH_HFE_tran">
    <type>transmission_interface/SimpleTransmission</type>
    <joint name="LH_HFE">
      <hardwareInterface>hardware_interface/EffortJointInterface</hardwareInterface>
    </joint>
    <actuator name="LH_HFE_motor">
      <hardwareInterface>hardware_interface/EffortJointInterface</hardwareInterface>
      <mechanicalReduction>1</mechanicalReduction>
    </actuator>
  </transmission>
  <transmission name="LH_KFE_tran">
    <type>transmission_interface/SimpleTransmission</type>
    <joint name="LH_KFE">
      <hardwareInterface>hardware_interface/EffortJointInterface</hardwareInterface>
    </joint>
    <actuator name="LH_KFE_motor">
      <hardwareInterface>hardware_interface/EffortJointInterface</hardwareInterface>
      <mechanicalReduction>1</mechanicalReduction>
    </actuator>
  </transmission>
  <!-- Robot Footprint -->
  <!-- <joint name="footprint_joint" type="fixed">
        <parent link="base"/>
        <child link="base_footprint"/>
        <origin xyz="0.0 0.0 -0.2" rpy="0 0 0"/>
    </joint>

    <link name="base_footprint">
      <inertial>
      <origin xyz="0 0 0" rpy="${pi/2} 0 ${pi/2}"/>      
      <mass value="0.001"/>
      <inertia ixx="0.0" ixy="0.0" ixz="0.0" iyy="0.0" iyz="0.0" izz="0.0"/>
    </inertial>
    </link>

    <xacro:lidar parent="base" xyz="-0.065 0. 0.1" rpy="0. 0. 0."/> -->
</robot>

